[2024-10-28T21:17:29.734+0000] {taskinstance.py:1103} INFO - Dependencies all met for dep_context=non-requeueable deps ti=<TaskInstance: api_binance_dag1.union_data_to_df manual__2024-10-28T21:17:20.352735+00:00 [queued]>
[2024-10-28T21:17:29.749+0000] {taskinstance.py:1103} INFO - Dependencies all met for dep_context=requeueable deps ti=<TaskInstance: api_binance_dag1.union_data_to_df manual__2024-10-28T21:17:20.352735+00:00 [queued]>
[2024-10-28T21:17:29.750+0000] {taskinstance.py:1308} INFO - Starting attempt 1 of 3
[2024-10-28T21:17:29.772+0000] {taskinstance.py:1327} INFO - Executing <Task(PythonOperator): union_data_to_df> on 2024-10-28 21:17:20.352735+00:00
[2024-10-28T21:17:29.782+0000] {standard_task_runner.py:57} INFO - Started process 249 to run task
[2024-10-28T21:17:29.787+0000] {standard_task_runner.py:84} INFO - Running: ['***', 'tasks', 'run', 'api_binance_dag1', 'union_data_to_df', 'manual__2024-10-28T21:17:20.352735+00:00', '--job-id', '732', '--raw', '--subdir', 'DAGS_FOLDER/binance.Dag1.py', '--cfg-path', '/tmp/tmp_w8_1buk']
[2024-10-28T21:17:29.790+0000] {standard_task_runner.py:85} INFO - Job 732: Subtask union_data_to_df
[2024-10-28T21:17:29.808+0000] {warnings.py:110} WARNING - /home/***/.local/lib/python3.7/site-packages/***/settings.py:195: DeprecationWarning: The sql_alchemy_conn option in [core] has been moved to the sql_alchemy_conn option in [database] - the old setting has been used, but please update your config.
  SQL_ALCHEMY_CONN = conf.get("database", "SQL_ALCHEMY_CONN")

[2024-10-28T21:17:29.869+0000] {task_command.py:410} INFO - Running <TaskInstance: api_binance_dag1.union_data_to_df manual__2024-10-28T21:17:20.352735+00:00 [running]> on host 3e776c2a96a1
[2024-10-28T21:17:30.215+0000] {taskinstance.py:1547} INFO - Exporting env vars: AIRFLOW_CTX_DAG_OWNER='Danil' AIRFLOW_CTX_DAG_ID='api_binance_dag1' AIRFLOW_CTX_TASK_ID='union_data_to_df' AIRFLOW_CTX_EXECUTION_DATE='2024-10-28T21:17:20.352735+00:00' AIRFLOW_CTX_TRY_NUMBER='1' AIRFLOW_CTX_DAG_RUN_ID='manual__2024-10-28T21:17:20.352735+00:00'
[2024-10-28T21:17:31.360+0000] {taskinstance.py:1824} ERROR - Task failed with exception
Traceback (most recent call last):
  File "/home/airflow/.local/lib/python3.7/site-packages/airflow/operators/python.py", line 181, in execute
    return_value = self.execute_callable()
  File "/home/airflow/.local/lib/python3.7/site-packages/airflow/operators/python.py", line 198, in execute_callable
    return self.python_callable(*self.op_args, **self.op_kwargs)
  File "/opt/airflow/dags/binance.Dag1.py", line 67, in push_from_xcom_to_df
    plt.figure()  # Создаем новую фигуру для каждого графика
NameError: name 'plt' is not defined
[2024-10-28T21:17:31.377+0000] {taskinstance.py:1350} INFO - Marking task as UP_FOR_RETRY. dag_id=api_binance_dag1, task_id=union_data_to_df, execution_date=20241028T211720, start_date=20241028T211729, end_date=20241028T211731
[2024-10-28T21:17:31.406+0000] {standard_task_runner.py:109} ERROR - Failed to execute job 732 for task union_data_to_df (name 'plt' is not defined; 249)
[2024-10-28T21:17:31.447+0000] {local_task_job_runner.py:225} INFO - Task exited with return code 1
[2024-10-28T21:17:31.489+0000] {taskinstance.py:2653} INFO - 0 downstream tasks scheduled from follow-on schedule check
