[2024-10-28T10:45:40.092+0000] {taskinstance.py:1103} INFO - Dependencies all met for dep_context=non-requeueable deps ti=<TaskInstance: api_binance_dag1.draw_smth_graphs manual__2024-10-23T20:40:46.209016+00:00 [queued]>
[2024-10-28T10:45:40.108+0000] {taskinstance.py:1103} INFO - Dependencies all met for dep_context=requeueable deps ti=<TaskInstance: api_binance_dag1.draw_smth_graphs manual__2024-10-23T20:40:46.209016+00:00 [queued]>
[2024-10-28T10:45:40.108+0000] {taskinstance.py:1308} INFO - Starting attempt 4 of 6
[2024-10-28T10:45:40.143+0000] {taskinstance.py:1327} INFO - Executing <Task(PythonOperator): draw_smth_graphs> on 2024-10-23 20:40:46.209016+00:00
[2024-10-28T10:45:40.162+0000] {standard_task_runner.py:57} INFO - Started process 208 to run task
[2024-10-28T10:45:40.166+0000] {standard_task_runner.py:84} INFO - Running: ['***', 'tasks', 'run', 'api_binance_dag1', 'draw_smth_graphs', 'manual__2024-10-23T20:40:46.209016+00:00', '--job-id', '586', '--raw', '--subdir', 'DAGS_FOLDER/binance.Dag1.py', '--cfg-path', '/tmp/tmpt0dcjswc']
[2024-10-28T10:45:40.169+0000] {standard_task_runner.py:85} INFO - Job 586: Subtask draw_smth_graphs
[2024-10-28T10:45:40.189+0000] {warnings.py:110} WARNING - /home/***/.local/lib/python3.7/site-packages/***/settings.py:195: DeprecationWarning: The sql_alchemy_conn option in [core] has been moved to the sql_alchemy_conn option in [database] - the old setting has been used, but please update your config.
  SQL_ALCHEMY_CONN = conf.get("database", "SQL_ALCHEMY_CONN")

[2024-10-28T10:45:40.259+0000] {task_command.py:410} INFO - Running <TaskInstance: api_binance_dag1.draw_smth_graphs manual__2024-10-23T20:40:46.209016+00:00 [running]> on host 3e776c2a96a1
[2024-10-28T10:45:40.444+0000] {taskinstance.py:1547} INFO - Exporting env vars: AIRFLOW_CTX_DAG_OWNER='Danil' AIRFLOW_CTX_DAG_ID='api_binance_dag1' AIRFLOW_CTX_TASK_ID='draw_smth_graphs' AIRFLOW_CTX_EXECUTION_DATE='2024-10-23T20:40:46.209016+00:00' AIRFLOW_CTX_TRY_NUMBER='4' AIRFLOW_CTX_DAG_RUN_ID='manual__2024-10-23T20:40:46.209016+00:00'
[2024-10-28T10:45:40.499+0000] {taskinstance.py:1824} ERROR - Task failed with exception
Traceback (most recent call last):
  File "/home/airflow/.local/lib/python3.7/site-packages/airflow/operators/python.py", line 181, in execute
    return_value = self.execute_callable()
  File "/home/airflow/.local/lib/python3.7/site-packages/airflow/operators/python.py", line 198, in execute_callable
    return self.python_callable(*self.op_args, **self.op_kwargs)
  File "/opt/airflow/dags/binance.Dag1.py", line 70, in draw_graphs
    final_df['Дата открытия'] = final_df['Дата открытия'].dt.strftime('%d.%m.%Y') #не понимаю, почему эта колонка не передалась в датаформате из предыдущего таска
  File "/home/airflow/.local/lib/python3.7/site-packages/pandas/core/generic.py", line 5487, in __getattr__
    return object.__getattribute__(self, name)
  File "/home/airflow/.local/lib/python3.7/site-packages/pandas/core/accessor.py", line 181, in __get__
    accessor_obj = self._accessor(obj)
  File "/home/airflow/.local/lib/python3.7/site-packages/pandas/core/indexes/accessors.py", line 506, in __new__
    raise AttributeError("Can only use .dt accessor with datetimelike values")
AttributeError: Can only use .dt accessor with datetimelike values
[2024-10-28T10:45:40.528+0000] {taskinstance.py:1350} INFO - Marking task as UP_FOR_RETRY. dag_id=api_binance_dag1, task_id=draw_smth_graphs, execution_date=20241023T204046, start_date=20241028T104540, end_date=20241028T104540
[2024-10-28T10:45:40.558+0000] {standard_task_runner.py:109} ERROR - Failed to execute job 586 for task draw_smth_graphs (Can only use .dt accessor with datetimelike values; 208)
[2024-10-28T10:45:40.580+0000] {local_task_job_runner.py:225} INFO - Task exited with return code 1
[2024-10-28T10:45:40.615+0000] {taskinstance.py:2653} INFO - 0 downstream tasks scheduled from follow-on schedule check
