[2024-10-21T17:37:56.561+0000] {taskinstance.py:1103} INFO - Dependencies all met for dep_context=non-requeueable deps ti=<TaskInstance: api_binance_dag1.union_data_to_df manual__2024-10-21T17:01:43.335906+00:00 [queued]>
[2024-10-21T17:37:56.596+0000] {taskinstance.py:1103} INFO - Dependencies all met for dep_context=requeueable deps ti=<TaskInstance: api_binance_dag1.union_data_to_df manual__2024-10-21T17:01:43.335906+00:00 [queued]>
[2024-10-21T17:37:56.597+0000] {taskinstance.py:1308} INFO - Starting attempt 4 of 6
[2024-10-21T17:37:56.636+0000] {taskinstance.py:1327} INFO - Executing <Task(PythonOperator): union_data_to_df> on 2024-10-21 17:01:43.335906+00:00
[2024-10-21T17:37:56.649+0000] {standard_task_runner.py:57} INFO - Started process 658 to run task
[2024-10-21T17:37:56.656+0000] {standard_task_runner.py:84} INFO - Running: ['***', 'tasks', 'run', 'api_binance_dag1', 'union_data_to_df', 'manual__2024-10-21T17:01:43.335906+00:00', '--job-id', '457', '--raw', '--subdir', 'DAGS_FOLDER/binance.Dag1.py', '--cfg-path', '/tmp/tmpanziccyd']
[2024-10-21T17:37:56.661+0000] {standard_task_runner.py:85} INFO - Job 457: Subtask union_data_to_df
[2024-10-21T17:37:56.697+0000] {warnings.py:110} WARNING - /home/***/.local/lib/python3.7/site-packages/***/settings.py:195: DeprecationWarning: The sql_alchemy_conn option in [core] has been moved to the sql_alchemy_conn option in [database] - the old setting has been used, but please update your config.
  SQL_ALCHEMY_CONN = conf.get("database", "SQL_ALCHEMY_CONN")

[2024-10-21T17:37:56.793+0000] {task_command.py:410} INFO - Running <TaskInstance: api_binance_dag1.union_data_to_df manual__2024-10-21T17:01:43.335906+00:00 [running]> on host 3e776c2a96a1
[2024-10-21T17:38:37.855+0000] {job.py:216} ERROR - Job heartbeat got an exception
Traceback (most recent call last):
  File "/home/airflow/.local/lib/python3.7/site-packages/sqlalchemy/engine/base.py", line 3366, in _wrap_pool_connect
    return fn()
  File "/home/airflow/.local/lib/python3.7/site-packages/sqlalchemy/pool/base.py", line 327, in connect
    return _ConnectionFairy._checkout(self)
  File "/home/airflow/.local/lib/python3.7/site-packages/sqlalchemy/pool/base.py", line 894, in _checkout
    fairy = _ConnectionRecord.checkout(pool)
  File "/home/airflow/.local/lib/python3.7/site-packages/sqlalchemy/pool/base.py", line 493, in checkout
    rec = pool._do_get()
  File "/home/airflow/.local/lib/python3.7/site-packages/sqlalchemy/pool/impl.py", line 256, in _do_get
    return self._create_connection()
  File "/home/airflow/.local/lib/python3.7/site-packages/sqlalchemy/pool/base.py", line 273, in _create_connection
    return _ConnectionRecord(self)
  File "/home/airflow/.local/lib/python3.7/site-packages/sqlalchemy/pool/base.py", line 388, in __init__
    self.__connect()
  File "/home/airflow/.local/lib/python3.7/site-packages/sqlalchemy/pool/base.py", line 691, in __connect
    pool.logger.debug("Error on connect(): %s", e)
  File "/home/airflow/.local/lib/python3.7/site-packages/sqlalchemy/util/langhelpers.py", line 72, in __exit__
    with_traceback=exc_tb,
  File "/home/airflow/.local/lib/python3.7/site-packages/sqlalchemy/util/compat.py", line 211, in raise_
    raise exception
  File "/home/airflow/.local/lib/python3.7/site-packages/sqlalchemy/pool/base.py", line 686, in __connect
    self.dbapi_connection = connection = pool._invoke_creator(self)
  File "/home/airflow/.local/lib/python3.7/site-packages/sqlalchemy/engine/create.py", line 574, in connect
    return dialect.connect(*cargs, **cparams)
  File "/home/airflow/.local/lib/python3.7/site-packages/sqlalchemy/engine/default.py", line 598, in connect
    return self.dbapi.connect(*cargs, **cparams)
  File "/home/airflow/.local/lib/python3.7/site-packages/psycopg2/__init__.py", line 122, in connect
    conn = _connect(dsn, connection_factory=connection_factory, **kwasync)
psycopg2.OperationalError: could not translate host name "postgres" to address: Temporary failure in name resolution


The above exception was the direct cause of the following exception:

Traceback (most recent call last):
  File "/home/airflow/.local/lib/python3.7/site-packages/airflow/jobs/job.py", line 187, in heartbeat
    session.merge(self)
  File "/home/airflow/.local/lib/python3.7/site-packages/sqlalchemy/orm/session.py", line 3062, in merge
    _resolve_conflict_map=_resolve_conflict_map,
  File "/home/airflow/.local/lib/python3.7/site-packages/sqlalchemy/orm/session.py", line 3140, in _merge
    options=options,
  File "/home/airflow/.local/lib/python3.7/site-packages/sqlalchemy/orm/session.py", line 2861, in get
    execution_options=execution_options,
  File "/home/airflow/.local/lib/python3.7/site-packages/sqlalchemy/orm/session.py", line 2979, in _get_impl
    load_options=load_options,
  File "/home/airflow/.local/lib/python3.7/site-packages/sqlalchemy/orm/loading.py", line 534, in load_on_pk_identity
    bind_arguments=bind_arguments,
  File "/home/airflow/.local/lib/python3.7/site-packages/sqlalchemy/orm/session.py", line 1716, in execute
    conn = self._connection_for_bind(bind)
  File "/home/airflow/.local/lib/python3.7/site-packages/sqlalchemy/orm/session.py", line 1556, in _connection_for_bind
    engine, execution_options
  File "/home/airflow/.local/lib/python3.7/site-packages/sqlalchemy/orm/session.py", line 750, in _connection_for_bind
    conn = bind.connect()
  File "/home/airflow/.local/lib/python3.7/site-packages/sqlalchemy/engine/base.py", line 3320, in connect
    return self._connection_cls(self, close_with_result=close_with_result)
  File "/home/airflow/.local/lib/python3.7/site-packages/sqlalchemy/engine/base.py", line 96, in __init__
    else engine.raw_connection()
  File "/home/airflow/.local/lib/python3.7/site-packages/sqlalchemy/engine/base.py", line 3399, in raw_connection
    return self._wrap_pool_connect(self.pool.connect, _connection)
  File "/home/airflow/.local/lib/python3.7/site-packages/sqlalchemy/engine/base.py", line 3370, in _wrap_pool_connect
    e, dialect, self
  File "/home/airflow/.local/lib/python3.7/site-packages/sqlalchemy/engine/base.py", line 2204, in _handle_dbapi_exception_noconnection
    sqlalchemy_exception, with_traceback=exc_info[2], from_=e
  File "/home/airflow/.local/lib/python3.7/site-packages/sqlalchemy/util/compat.py", line 211, in raise_
    raise exception
  File "/home/airflow/.local/lib/python3.7/site-packages/sqlalchemy/engine/base.py", line 3366, in _wrap_pool_connect
    return fn()
  File "/home/airflow/.local/lib/python3.7/site-packages/sqlalchemy/pool/base.py", line 327, in connect
    return _ConnectionFairy._checkout(self)
  File "/home/airflow/.local/lib/python3.7/site-packages/sqlalchemy/pool/base.py", line 894, in _checkout
    fairy = _ConnectionRecord.checkout(pool)
  File "/home/airflow/.local/lib/python3.7/site-packages/sqlalchemy/pool/base.py", line 493, in checkout
    rec = pool._do_get()
  File "/home/airflow/.local/lib/python3.7/site-packages/sqlalchemy/pool/impl.py", line 256, in _do_get
    return self._create_connection()
  File "/home/airflow/.local/lib/python3.7/site-packages/sqlalchemy/pool/base.py", line 273, in _create_connection
    return _ConnectionRecord(self)
  File "/home/airflow/.local/lib/python3.7/site-packages/sqlalchemy/pool/base.py", line 388, in __init__
    self.__connect()
  File "/home/airflow/.local/lib/python3.7/site-packages/sqlalchemy/pool/base.py", line 691, in __connect
    pool.logger.debug("Error on connect(): %s", e)
  File "/home/airflow/.local/lib/python3.7/site-packages/sqlalchemy/util/langhelpers.py", line 72, in __exit__
    with_traceback=exc_tb,
  File "/home/airflow/.local/lib/python3.7/site-packages/sqlalchemy/util/compat.py", line 211, in raise_
    raise exception
  File "/home/airflow/.local/lib/python3.7/site-packages/sqlalchemy/pool/base.py", line 686, in __connect
    self.dbapi_connection = connection = pool._invoke_creator(self)
  File "/home/airflow/.local/lib/python3.7/site-packages/sqlalchemy/engine/create.py", line 574, in connect
    return dialect.connect(*cargs, **cparams)
  File "/home/airflow/.local/lib/python3.7/site-packages/sqlalchemy/engine/default.py", line 598, in connect
    return self.dbapi.connect(*cargs, **cparams)
  File "/home/airflow/.local/lib/python3.7/site-packages/psycopg2/__init__.py", line 122, in connect
    conn = _connect(dsn, connection_factory=connection_factory, **kwasync)
sqlalchemy.exc.OperationalError: (psycopg2.OperationalError) could not translate host name "postgres" to address: Temporary failure in name resolution

(Background on this error at: https://sqlalche.me/e/14/e3q8)
[2024-10-21T17:38:42.304+0000] {taskinstance.py:1547} INFO - Exporting env vars: AIRFLOW_CTX_DAG_OWNER='Danil' AIRFLOW_CTX_DAG_ID='api_binance_dag1' AIRFLOW_CTX_TASK_ID='union_data_to_df' AIRFLOW_CTX_EXECUTION_DATE='2024-10-21T17:01:43.335906+00:00' AIRFLOW_CTX_TRY_NUMBER='4' AIRFLOW_CTX_DAG_RUN_ID='manual__2024-10-21T17:01:43.335906+00:00'
[2024-10-21T17:38:42.733+0000] {logging_mixin.py:149} INFO -    Имя монеты Дата открытия          High           Low         Close
0         SOL    2024-10-12  147.32000000  144.71000000  146.40000000
1         SOL    2024-10-13  148.86000000  144.45000000  147.74000000
2         SOL    2024-10-14  158.10000000  146.80000000  157.59000000
3         SOL    2024-10-15  159.73000000  150.30000000  154.76000000
4         SOL    2024-10-16  158.41000000  153.00000000  154.28000000
5         SOL    2024-10-17  155.73000000  147.66000000  150.50000000
6         SOL    2024-10-18  156.65000000  149.56000000  154.94000000
7       1INCH    2024-10-12    0.26350000    0.25640000    0.25990000
8       1INCH    2024-10-13    0.26300000    0.25090000    0.25690000
9       1INCH    2024-10-14    0.27340000    0.25390000    0.27170000
10      1INCH    2024-10-15    0.27780000    0.25790000    0.27730000
11      1INCH    2024-10-16    0.28160000    0.26510000    0.27040000
12      1INCH    2024-10-17    0.27220000    0.25700000    0.26200000
13      1INCH    2024-10-18    0.27140000    0.25960000    0.27060000
14        SUI    2024-10-12    2.28820000    2.00320000    2.24150000
15        SUI    2024-10-13    2.36800000    2.12350000    2.34380000
16        SUI    2024-10-14    2.34980000    2.20890000    2.25010000
17        SUI    2024-10-15    2.27480000    1.97250000    2.05970000
18        SUI    2024-10-16    2.15520000    1.97580000    2.08280000
19        SUI    2024-10-17    2.16310000    1.99730000    2.02490000
20        SUI    2024-10-18    2.15280000    2.00880000    2.12560000
21        TON    2024-10-12    5.31300000    5.15100000    5.24100000
22        TON    2024-10-13    5.30800000    5.11300000    5.19200000
23        TON    2024-10-14    5.36000000    5.15900000    5.32300000
24        TON    2024-10-15    5.34300000    5.12300000    5.22400000
25        TON    2024-10-16    5.30000000    5.17000000    5.22700000
26        TON    2024-10-17    5.26000000    5.10500000    5.18300000
27        TON    2024-10-18    5.26500000    5.17300000    5.25000000
28       STRK    2024-10-12    0.43080000    0.40570000    0.42200000
29       STRK    2024-10-13    0.43780000    0.40740000    0.42040000
30       STRK    2024-10-14    0.44890000    0.41440000    0.44090000
31       STRK    2024-10-15    0.44470000    0.41210000    0.42550000
32       STRK    2024-10-16    0.43270000    0.40850000    0.41330000
33       STRK    2024-10-17    0.42050000    0.38710000    0.39270000
34       STRK    2024-10-18    0.40940000    0.38660000    0.40460000
[2024-10-21T17:38:42.735+0000] {python.py:183} INFO - Done. Returned value was: None
[2024-10-21T17:38:42.757+0000] {taskinstance.py:1350} INFO - Marking task as SUCCESS. dag_id=api_binance_dag1, task_id=union_data_to_df, execution_date=20241021T170143, start_date=20241021T173756, end_date=20241021T173842
[2024-10-21T17:38:42.851+0000] {local_task_job_runner.py:225} INFO - Task exited with return code 0
[2024-10-21T17:38:42.911+0000] {taskinstance.py:2653} INFO - 1 downstream tasks scheduled from follow-on schedule check
