[2024-10-28T11:29:45.395+0000] {taskinstance.py:1103} INFO - Dependencies all met for dep_context=non-requeueable deps ti=<TaskInstance: api_binance_dag1.SUI manual__2024-10-28T11:23:05.453516+00:00 [queued]>
[2024-10-28T11:29:45.467+0000] {taskinstance.py:1103} INFO - Dependencies all met for dep_context=requeueable deps ti=<TaskInstance: api_binance_dag1.SUI manual__2024-10-28T11:23:05.453516+00:00 [queued]>
[2024-10-28T11:29:45.468+0000] {taskinstance.py:1308} INFO - Starting attempt 1 of 3
[2024-10-28T11:29:45.540+0000] {taskinstance.py:1327} INFO - Executing <Task(PythonOperator): SUI> on 2024-10-28 11:23:05.453516+00:00
[2024-10-28T11:29:45.557+0000] {standard_task_runner.py:57} INFO - Started process 78 to run task
[2024-10-28T11:29:45.580+0000] {standard_task_runner.py:84} INFO - Running: ['***', 'tasks', 'run', 'api_binance_dag1', 'SUI', 'manual__2024-10-28T11:23:05.453516+00:00', '--job-id', '624', '--raw', '--subdir', 'DAGS_FOLDER/binance.Dag1.py', '--cfg-path', '/tmp/tmp5mh_2edz']
[2024-10-28T11:29:45.584+0000] {standard_task_runner.py:85} INFO - Job 624: Subtask SUI
[2024-10-28T11:29:45.682+0000] {warnings.py:110} WARNING - /home/***/.local/lib/python3.7/site-packages/***/settings.py:195: DeprecationWarning: The sql_alchemy_conn option in [core] has been moved to the sql_alchemy_conn option in [database] - the old setting has been used, but please update your config.
  SQL_ALCHEMY_CONN = conf.get("database", "SQL_ALCHEMY_CONN")

[2024-10-28T11:29:45.974+0000] {task_command.py:410} INFO - Running <TaskInstance: api_binance_dag1.SUI manual__2024-10-28T11:23:05.453516+00:00 [running]> on host 3e776c2a96a1
[2024-10-28T11:30:12.570+0000] {job.py:216} ERROR - Job heartbeat got an exception
Traceback (most recent call last):
  File "/home/airflow/.local/lib/python3.7/site-packages/sqlalchemy/engine/base.py", line 3366, in _wrap_pool_connect
    return fn()
  File "/home/airflow/.local/lib/python3.7/site-packages/sqlalchemy/pool/base.py", line 327, in connect
    return _ConnectionFairy._checkout(self)
  File "/home/airflow/.local/lib/python3.7/site-packages/sqlalchemy/pool/base.py", line 894, in _checkout
    fairy = _ConnectionRecord.checkout(pool)
  File "/home/airflow/.local/lib/python3.7/site-packages/sqlalchemy/pool/base.py", line 493, in checkout
    rec = pool._do_get()
  File "/home/airflow/.local/lib/python3.7/site-packages/sqlalchemy/pool/impl.py", line 256, in _do_get
    return self._create_connection()
  File "/home/airflow/.local/lib/python3.7/site-packages/sqlalchemy/pool/base.py", line 273, in _create_connection
    return _ConnectionRecord(self)
  File "/home/airflow/.local/lib/python3.7/site-packages/sqlalchemy/pool/base.py", line 388, in __init__
    self.__connect()
  File "/home/airflow/.local/lib/python3.7/site-packages/sqlalchemy/pool/base.py", line 691, in __connect
    pool.logger.debug("Error on connect(): %s", e)
  File "/home/airflow/.local/lib/python3.7/site-packages/sqlalchemy/util/langhelpers.py", line 72, in __exit__
    with_traceback=exc_tb,
  File "/home/airflow/.local/lib/python3.7/site-packages/sqlalchemy/util/compat.py", line 211, in raise_
    raise exception
  File "/home/airflow/.local/lib/python3.7/site-packages/sqlalchemy/pool/base.py", line 686, in __connect
    self.dbapi_connection = connection = pool._invoke_creator(self)
  File "/home/airflow/.local/lib/python3.7/site-packages/sqlalchemy/engine/create.py", line 574, in connect
    return dialect.connect(*cargs, **cparams)
  File "/home/airflow/.local/lib/python3.7/site-packages/sqlalchemy/engine/default.py", line 598, in connect
    return self.dbapi.connect(*cargs, **cparams)
  File "/home/airflow/.local/lib/python3.7/site-packages/psycopg2/__init__.py", line 122, in connect
    conn = _connect(dsn, connection_factory=connection_factory, **kwasync)
psycopg2.OperationalError: could not translate host name "postgres" to address: Temporary failure in name resolution


The above exception was the direct cause of the following exception:

Traceback (most recent call last):
  File "/home/airflow/.local/lib/python3.7/site-packages/airflow/jobs/job.py", line 187, in heartbeat
    session.merge(self)
  File "/home/airflow/.local/lib/python3.7/site-packages/sqlalchemy/orm/session.py", line 3062, in merge
    _resolve_conflict_map=_resolve_conflict_map,
  File "/home/airflow/.local/lib/python3.7/site-packages/sqlalchemy/orm/session.py", line 3140, in _merge
    options=options,
  File "/home/airflow/.local/lib/python3.7/site-packages/sqlalchemy/orm/session.py", line 2861, in get
    execution_options=execution_options,
  File "/home/airflow/.local/lib/python3.7/site-packages/sqlalchemy/orm/session.py", line 2979, in _get_impl
    load_options=load_options,
  File "/home/airflow/.local/lib/python3.7/site-packages/sqlalchemy/orm/loading.py", line 534, in load_on_pk_identity
    bind_arguments=bind_arguments,
  File "/home/airflow/.local/lib/python3.7/site-packages/sqlalchemy/orm/session.py", line 1716, in execute
    conn = self._connection_for_bind(bind)
  File "/home/airflow/.local/lib/python3.7/site-packages/sqlalchemy/orm/session.py", line 1556, in _connection_for_bind
    engine, execution_options
  File "/home/airflow/.local/lib/python3.7/site-packages/sqlalchemy/orm/session.py", line 750, in _connection_for_bind
    conn = bind.connect()
  File "/home/airflow/.local/lib/python3.7/site-packages/sqlalchemy/engine/base.py", line 3320, in connect
    return self._connection_cls(self, close_with_result=close_with_result)
  File "/home/airflow/.local/lib/python3.7/site-packages/sqlalchemy/engine/base.py", line 96, in __init__
    else engine.raw_connection()
  File "/home/airflow/.local/lib/python3.7/site-packages/sqlalchemy/engine/base.py", line 3399, in raw_connection
    return self._wrap_pool_connect(self.pool.connect, _connection)
  File "/home/airflow/.local/lib/python3.7/site-packages/sqlalchemy/engine/base.py", line 3370, in _wrap_pool_connect
    e, dialect, self
  File "/home/airflow/.local/lib/python3.7/site-packages/sqlalchemy/engine/base.py", line 2204, in _handle_dbapi_exception_noconnection
    sqlalchemy_exception, with_traceback=exc_info[2], from_=e
  File "/home/airflow/.local/lib/python3.7/site-packages/sqlalchemy/util/compat.py", line 211, in raise_
    raise exception
  File "/home/airflow/.local/lib/python3.7/site-packages/sqlalchemy/engine/base.py", line 3366, in _wrap_pool_connect
    return fn()
  File "/home/airflow/.local/lib/python3.7/site-packages/sqlalchemy/pool/base.py", line 327, in connect
    return _ConnectionFairy._checkout(self)
  File "/home/airflow/.local/lib/python3.7/site-packages/sqlalchemy/pool/base.py", line 894, in _checkout
    fairy = _ConnectionRecord.checkout(pool)
  File "/home/airflow/.local/lib/python3.7/site-packages/sqlalchemy/pool/base.py", line 493, in checkout
    rec = pool._do_get()
  File "/home/airflow/.local/lib/python3.7/site-packages/sqlalchemy/pool/impl.py", line 256, in _do_get
    return self._create_connection()
  File "/home/airflow/.local/lib/python3.7/site-packages/sqlalchemy/pool/base.py", line 273, in _create_connection
    return _ConnectionRecord(self)
  File "/home/airflow/.local/lib/python3.7/site-packages/sqlalchemy/pool/base.py", line 388, in __init__
    self.__connect()
  File "/home/airflow/.local/lib/python3.7/site-packages/sqlalchemy/pool/base.py", line 691, in __connect
    pool.logger.debug("Error on connect(): %s", e)
  File "/home/airflow/.local/lib/python3.7/site-packages/sqlalchemy/util/langhelpers.py", line 72, in __exit__
    with_traceback=exc_tb,
  File "/home/airflow/.local/lib/python3.7/site-packages/sqlalchemy/util/compat.py", line 211, in raise_
    raise exception
  File "/home/airflow/.local/lib/python3.7/site-packages/sqlalchemy/pool/base.py", line 686, in __connect
    self.dbapi_connection = connection = pool._invoke_creator(self)
  File "/home/airflow/.local/lib/python3.7/site-packages/sqlalchemy/engine/create.py", line 574, in connect
    return dialect.connect(*cargs, **cparams)
  File "/home/airflow/.local/lib/python3.7/site-packages/sqlalchemy/engine/default.py", line 598, in connect
    return self.dbapi.connect(*cargs, **cparams)
  File "/home/airflow/.local/lib/python3.7/site-packages/psycopg2/__init__.py", line 122, in connect
    conn = _connect(dsn, connection_factory=connection_factory, **kwasync)
sqlalchemy.exc.OperationalError: (psycopg2.OperationalError) could not translate host name "postgres" to address: Temporary failure in name resolution

(Background on this error at: https://sqlalche.me/e/14/e3q8)
[2024-10-28T11:30:22.102+0000] {taskinstance.py:1547} INFO - Exporting env vars: AIRFLOW_CTX_DAG_OWNER='Danil' AIRFLOW_CTX_DAG_ID='api_binance_dag1' AIRFLOW_CTX_TASK_ID='SUI' AIRFLOW_CTX_EXECUTION_DATE='2024-10-28T11:23:05.453516+00:00' AIRFLOW_CTX_TRY_NUMBER='1' AIRFLOW_CTX_DAG_RUN_ID='manual__2024-10-28T11:23:05.453516+00:00'
[2024-10-28T11:30:23.151+0000] {logging_mixin.py:149} INFO - Pushed to XCom: Key: SUI, Value: [[1729296000000, '2.12560000', '2.12560000', '2.04010000', '2.06280000', '32190754.00000000', 1729382399999, '66654150.51482000', 199851, '15707822.30000000', '32525253.55075000', '0'], [1729382400000, '2.06270000', '2.15430000', '2.04330000', '2.12820000', '56575161.40000000', 1729468799999, '118824426.01660000', 316315, '29549413.60000000', '62094336.11160000', '0'], [1729468800000, '2.12830000', '2.17960000', '1.99720000', '2.00960000', '69497941.00000000', 1729555199999, '144125395.90362000', 334492, '34537740.70000000', '71602085.96779000', '0'], [1729555200000, '2.00960000', '2.03360000', '1.87580000', '1.93930000', '73977532.50000000', 1729641599999, '144497057.92839000', 365427, '35645478.30000000', '69678736.92210000', '0'], [1729641600000, '1.93940000', '1.99900000', '1.86570000', '1.97750000', '78991736.40000000', 1729727999999, '151871724.05779000', 378719, '40063511.80000000', '77102280.02783000', '0'], [1729728000000, '1.97750000', '2.05180000', '1.92500000', '1.93690000', '59493671.40000000', 1729814399999, '118241789.01801000', 318322, '28177209.50000000', '56029351.67442000', '0'], [1729814400000, '1.93700000', '1.94430000', '1.64000000', '1.75200000', '86182096.10000000', 1729900799999, '158309761.14473000', 408407, '39921865.20000000', '73448179.93040000', '0'], [1729900800000, '1.75200000', '1.84640000', '1.70040000', '1.79500000', '65712671.00000000', 1729987199999, '116305048.48325000', 319395, '33411314.60000000', '59148626.04672000', '0'], [1729987200000, '1.79520000', '1.82700000', '1.72480000', '1.75590000', '42099096.90000000', 1730073599999, '74837177.35224000', 250315, '20802732.00000000', '37010575.49128000', '0'], [1730073600000, '1.75590000', '1.76130000', '1.65480000', '1.70500000', '38775823.00000000', 1730159999999, '66284656.73898000', 188827, '18732624.40000000', '32025206.27036000', '0']]
[2024-10-28T11:30:23.157+0000] {python.py:183} INFO - Done. Returned value was: None
[2024-10-28T11:30:23.209+0000] {taskinstance.py:1350} INFO - Marking task as SUCCESS. dag_id=api_binance_dag1, task_id=SUI, execution_date=20241028T112305, start_date=20241028T112945, end_date=20241028T113023
[2024-10-28T11:30:23.310+0000] {local_task_job_runner.py:225} INFO - Task exited with return code 0
[2024-10-28T11:30:23.489+0000] {taskinstance.py:2653} INFO - 0 downstream tasks scheduled from follow-on schedule check
