[2024-10-16T17:53:49.573+0000] {taskinstance.py:1103} INFO - Dependencies all met for dep_context=non-requeueable deps ti=<TaskInstance: api_binance_dag1.1INCH manual__2024-10-15T22:17:22.494373+00:00 [queued]>
[2024-10-16T17:53:49.589+0000] {taskinstance.py:1103} INFO - Dependencies all met for dep_context=requeueable deps ti=<TaskInstance: api_binance_dag1.1INCH manual__2024-10-15T22:17:22.494373+00:00 [queued]>
[2024-10-16T17:53:49.590+0000] {taskinstance.py:1308} INFO - Starting attempt 2 of 6
[2024-10-16T17:53:49.611+0000] {taskinstance.py:1327} INFO - Executing <Task(PythonOperator): 1INCH> on 2024-10-15 22:17:22.494373+00:00
[2024-10-16T17:53:49.623+0000] {standard_task_runner.py:57} INFO - Started process 193 to run task
[2024-10-16T17:53:49.627+0000] {standard_task_runner.py:84} INFO - Running: ['***', 'tasks', 'run', 'api_binance_dag1', '1INCH', 'manual__2024-10-15T22:17:22.494373+00:00', '--job-id', '199', '--raw', '--subdir', 'DAGS_FOLDER/binance.Dag1.py', '--cfg-path', '/tmp/tmpfmx28x9_']
[2024-10-16T17:53:49.631+0000] {standard_task_runner.py:85} INFO - Job 199: Subtask 1INCH
[2024-10-16T17:53:49.650+0000] {warnings.py:110} WARNING - /home/***/.local/lib/python3.7/site-packages/***/settings.py:195: DeprecationWarning: The sql_alchemy_conn option in [core] has been moved to the sql_alchemy_conn option in [database] - the old setting has been used, but please update your config.
  SQL_ALCHEMY_CONN = conf.get("database", "SQL_ALCHEMY_CONN")

[2024-10-16T17:53:49.701+0000] {task_command.py:410} INFO - Running <TaskInstance: api_binance_dag1.1INCH manual__2024-10-15T22:17:22.494373+00:00 [running]> on host 3e776c2a96a1
[2024-10-16T17:53:49.842+0000] {taskinstance.py:1547} INFO - Exporting env vars: AIRFLOW_CTX_DAG_OWNER='Danil' AIRFLOW_CTX_DAG_ID='api_binance_dag1' AIRFLOW_CTX_TASK_ID='1INCH' AIRFLOW_CTX_EXECUTION_DATE='2024-10-15T22:17:22.494373+00:00' AIRFLOW_CTX_TRY_NUMBER='2' AIRFLOW_CTX_DAG_RUN_ID='manual__2024-10-15T22:17:22.494373+00:00'
[2024-10-16T17:53:50.877+0000] {taskinstance.py:1824} ERROR - Task failed with exception
Traceback (most recent call last):
  File "/home/airflow/.local/lib/python3.7/site-packages/urllib3/connection.py", line 175, in _new_conn
    (self._dns_host, self.port), self.timeout, **extra_kw
  File "/home/airflow/.local/lib/python3.7/site-packages/urllib3/util/connection.py", line 72, in create_connection
    for res in socket.getaddrinfo(host, port, family, socket.SOCK_STREAM):
  File "/usr/local/lib/python3.7/socket.py", line 752, in getaddrinfo
    for res in _socket.getaddrinfo(host, port, family, type, proto, flags):
socket.gaierror: [Errno -2] Name or service not known

During handling of the above exception, another exception occurred:

Traceback (most recent call last):
  File "/home/airflow/.local/lib/python3.7/site-packages/urllib3/connectionpool.py", line 721, in urlopen
    chunked=chunked,
  File "/home/airflow/.local/lib/python3.7/site-packages/urllib3/connectionpool.py", line 403, in _make_request
    self._validate_conn(conn)
  File "/home/airflow/.local/lib/python3.7/site-packages/urllib3/connectionpool.py", line 1053, in _validate_conn
    conn.connect()
  File "/home/airflow/.local/lib/python3.7/site-packages/urllib3/connection.py", line 363, in connect
    self.sock = conn = self._new_conn()
  File "/home/airflow/.local/lib/python3.7/site-packages/urllib3/connection.py", line 187, in _new_conn
    self, "Failed to establish a new connection: %s" % e
urllib3.exceptions.NewConnectionError: <urllib3.connection.HTTPSConnection object at 0x7f32b1d02450>: Failed to establish a new connection: [Errno -2] Name or service not known

During handling of the above exception, another exception occurred:

Traceback (most recent call last):
  File "/home/airflow/.local/lib/python3.7/site-packages/requests/adapters.py", line 497, in send
    chunked=chunked,
  File "/home/airflow/.local/lib/python3.7/site-packages/urllib3/connectionpool.py", line 799, in urlopen
    method, url, error=e, _pool=self, _stacktrace=sys.exc_info()[2]
  File "/home/airflow/.local/lib/python3.7/site-packages/urllib3/util/retry.py", line 592, in increment
    raise MaxRetryError(_pool, url, error or ResponseError(cause))
urllib3.exceptions.MaxRetryError: HTTPSConnectionPool(host='api.binance.com', port=443): Max retries exceeded with url: /api/v3/klines?symbol=1INCHUSDT&interval=1d&startTime=1728237229844&endTime=1729101229844&limit=7 (Caused by NewConnectionError('<urllib3.connection.HTTPSConnection object at 0x7f32b1d02450>: Failed to establish a new connection: [Errno -2] Name or service not known'))

During handling of the above exception, another exception occurred:

Traceback (most recent call last):
  File "/home/airflow/.local/lib/python3.7/site-packages/airflow/operators/python.py", line 181, in execute
    return_value = self.execute_callable()
  File "/home/airflow/.local/lib/python3.7/site-packages/airflow/operators/python.py", line 198, in execute_callable
    return self.python_callable(*self.op_args, **self.op_kwargs)
  File "/opt/airflow/dags/binance.Dag1.py", line 38, in pull_tokens_csv
    response: str = requests.get(url, params=params)
  File "/home/airflow/.local/lib/python3.7/site-packages/requests/api.py", line 73, in get
    return request("get", url, params=params, **kwargs)
  File "/home/airflow/.local/lib/python3.7/site-packages/requests/api.py", line 59, in request
    return session.request(method=method, url=url, **kwargs)
  File "/home/airflow/.local/lib/python3.7/site-packages/requests/sessions.py", line 589, in request
    resp = self.send(prep, **send_kwargs)
  File "/home/airflow/.local/lib/python3.7/site-packages/requests/sessions.py", line 703, in send
    r = adapter.send(request, **kwargs)
  File "/home/airflow/.local/lib/python3.7/site-packages/requests/adapters.py", line 519, in send
    raise ConnectionError(e, request=request)
requests.exceptions.ConnectionError: HTTPSConnectionPool(host='api.binance.com', port=443): Max retries exceeded with url: /api/v3/klines?symbol=1INCHUSDT&interval=1d&startTime=1728237229844&endTime=1729101229844&limit=7 (Caused by NewConnectionError('<urllib3.connection.HTTPSConnection object at 0x7f32b1d02450>: Failed to establish a new connection: [Errno -2] Name or service not known'))
[2024-10-16T17:53:50.950+0000] {taskinstance.py:1350} INFO - Marking task as UP_FOR_RETRY. dag_id=api_binance_dag1, task_id=1INCH, execution_date=20241015T221722, start_date=20241016T175349, end_date=20241016T175350
[2024-10-16T17:53:51.237+0000] {standard_task_runner.py:109} ERROR - Failed to execute job 199 for task 1INCH (HTTPSConnectionPool(host='api.binance.com', port=443): Max retries exceeded with url: /api/v3/klines?symbol=1INCHUSDT&interval=1d&startTime=1728237229844&endTime=1729101229844&limit=7 (Caused by NewConnectionError('<urllib3.connection.HTTPSConnection object at 0x7f32b1d02450>: Failed to establish a new connection: [Errno -2] Name or service not known')); 193)
[2024-10-16T17:53:51.288+0000] {local_task_job_runner.py:225} INFO - Task exited with return code 1
[2024-10-16T17:53:51.372+0000] {taskinstance.py:2653} INFO - 0 downstream tasks scheduled from follow-on schedule check
