[2024-10-28T21:50:32.104+0000] {taskinstance.py:1103} INFO - Dependencies all met for dep_context=non-requeueable deps ti=<TaskInstance: api_binance_dag1.STRK manual__2024-10-28T21:50:17.159772+00:00 [queued]>
[2024-10-28T21:50:32.132+0000] {taskinstance.py:1103} INFO - Dependencies all met for dep_context=requeueable deps ti=<TaskInstance: api_binance_dag1.STRK manual__2024-10-28T21:50:17.159772+00:00 [queued]>
[2024-10-28T21:50:32.133+0000] {taskinstance.py:1308} INFO - Starting attempt 1 of 3
[2024-10-28T21:50:32.163+0000] {taskinstance.py:1327} INFO - Executing <Task(PythonOperator): STRK> on 2024-10-28 21:50:17.159772+00:00
[2024-10-28T21:50:32.182+0000] {standard_task_runner.py:57} INFO - Started process 371 to run task
[2024-10-28T21:50:32.196+0000] {standard_task_runner.py:84} INFO - Running: ['***', 'tasks', 'run', 'api_binance_dag1', 'STRK', 'manual__2024-10-28T21:50:17.159772+00:00', '--job-id', '770', '--raw', '--subdir', 'DAGS_FOLDER/binance.Dag1.py', '--cfg-path', '/tmp/tmpf66pafp3']
[2024-10-28T21:50:32.204+0000] {standard_task_runner.py:85} INFO - Job 770: Subtask STRK
[2024-10-28T21:50:42.377+0000] {cli_action_loggers.py:135} WARNING - Failed to log action (psycopg2.OperationalError) could not translate host name "postgres" to address: Temporary failure in name resolution

(Background on this error at: https://sqlalche.me/e/14/e3q8)
[2024-10-28T21:50:42.868+0000] {warnings.py:110} WARNING - /home/***/.local/lib/python3.7/site-packages/***/settings.py:195: DeprecationWarning: The sql_alchemy_conn option in [core] has been moved to the sql_alchemy_conn option in [database] - the old setting has been used, but please update your config.
  SQL_ALCHEMY_CONN = conf.get("database", "SQL_ALCHEMY_CONN")

[2024-10-28T21:50:56.347+0000] {job.py:216} ERROR - Job heartbeat got an exception
Traceback (most recent call last):
  File "/home/airflow/.local/lib/python3.7/site-packages/sqlalchemy/engine/base.py", line 3366, in _wrap_pool_connect
    return fn()
  File "/home/airflow/.local/lib/python3.7/site-packages/sqlalchemy/pool/base.py", line 327, in connect
    return _ConnectionFairy._checkout(self)
  File "/home/airflow/.local/lib/python3.7/site-packages/sqlalchemy/pool/base.py", line 894, in _checkout
    fairy = _ConnectionRecord.checkout(pool)
  File "/home/airflow/.local/lib/python3.7/site-packages/sqlalchemy/pool/base.py", line 493, in checkout
    rec = pool._do_get()
  File "/home/airflow/.local/lib/python3.7/site-packages/sqlalchemy/pool/impl.py", line 256, in _do_get
    return self._create_connection()
  File "/home/airflow/.local/lib/python3.7/site-packages/sqlalchemy/pool/base.py", line 273, in _create_connection
    return _ConnectionRecord(self)
  File "/home/airflow/.local/lib/python3.7/site-packages/sqlalchemy/pool/base.py", line 388, in __init__
    self.__connect()
  File "/home/airflow/.local/lib/python3.7/site-packages/sqlalchemy/pool/base.py", line 691, in __connect
    pool.logger.debug("Error on connect(): %s", e)
  File "/home/airflow/.local/lib/python3.7/site-packages/sqlalchemy/util/langhelpers.py", line 72, in __exit__
    with_traceback=exc_tb,
  File "/home/airflow/.local/lib/python3.7/site-packages/sqlalchemy/util/compat.py", line 211, in raise_
    raise exception
  File "/home/airflow/.local/lib/python3.7/site-packages/sqlalchemy/pool/base.py", line 686, in __connect
    self.dbapi_connection = connection = pool._invoke_creator(self)
  File "/home/airflow/.local/lib/python3.7/site-packages/sqlalchemy/engine/create.py", line 574, in connect
    return dialect.connect(*cargs, **cparams)
  File "/home/airflow/.local/lib/python3.7/site-packages/sqlalchemy/engine/default.py", line 598, in connect
    return self.dbapi.connect(*cargs, **cparams)
  File "/home/airflow/.local/lib/python3.7/site-packages/psycopg2/__init__.py", line 122, in connect
    conn = _connect(dsn, connection_factory=connection_factory, **kwasync)
psycopg2.OperationalError: could not translate host name "postgres" to address: Temporary failure in name resolution


The above exception was the direct cause of the following exception:

Traceback (most recent call last):
  File "/home/airflow/.local/lib/python3.7/site-packages/airflow/jobs/job.py", line 187, in heartbeat
    session.merge(self)
  File "/home/airflow/.local/lib/python3.7/site-packages/sqlalchemy/orm/session.py", line 3062, in merge
    _resolve_conflict_map=_resolve_conflict_map,
  File "/home/airflow/.local/lib/python3.7/site-packages/sqlalchemy/orm/session.py", line 3140, in _merge
    options=options,
  File "/home/airflow/.local/lib/python3.7/site-packages/sqlalchemy/orm/session.py", line 2861, in get
    execution_options=execution_options,
  File "/home/airflow/.local/lib/python3.7/site-packages/sqlalchemy/orm/session.py", line 2979, in _get_impl
    load_options=load_options,
  File "/home/airflow/.local/lib/python3.7/site-packages/sqlalchemy/orm/loading.py", line 534, in load_on_pk_identity
    bind_arguments=bind_arguments,
  File "/home/airflow/.local/lib/python3.7/site-packages/sqlalchemy/orm/session.py", line 1716, in execute
    conn = self._connection_for_bind(bind)
  File "/home/airflow/.local/lib/python3.7/site-packages/sqlalchemy/orm/session.py", line 1556, in _connection_for_bind
    engine, execution_options
  File "/home/airflow/.local/lib/python3.7/site-packages/sqlalchemy/orm/session.py", line 750, in _connection_for_bind
    conn = bind.connect()
  File "/home/airflow/.local/lib/python3.7/site-packages/sqlalchemy/engine/base.py", line 3320, in connect
    return self._connection_cls(self, close_with_result=close_with_result)
  File "/home/airflow/.local/lib/python3.7/site-packages/sqlalchemy/engine/base.py", line 96, in __init__
    else engine.raw_connection()
  File "/home/airflow/.local/lib/python3.7/site-packages/sqlalchemy/engine/base.py", line 3399, in raw_connection
    return self._wrap_pool_connect(self.pool.connect, _connection)
  File "/home/airflow/.local/lib/python3.7/site-packages/sqlalchemy/engine/base.py", line 3370, in _wrap_pool_connect
    e, dialect, self
  File "/home/airflow/.local/lib/python3.7/site-packages/sqlalchemy/engine/base.py", line 2204, in _handle_dbapi_exception_noconnection
    sqlalchemy_exception, with_traceback=exc_info[2], from_=e
  File "/home/airflow/.local/lib/python3.7/site-packages/sqlalchemy/util/compat.py", line 211, in raise_
    raise exception
  File "/home/airflow/.local/lib/python3.7/site-packages/sqlalchemy/engine/base.py", line 3366, in _wrap_pool_connect
    return fn()
  File "/home/airflow/.local/lib/python3.7/site-packages/sqlalchemy/pool/base.py", line 327, in connect
    return _ConnectionFairy._checkout(self)
  File "/home/airflow/.local/lib/python3.7/site-packages/sqlalchemy/pool/base.py", line 894, in _checkout
    fairy = _ConnectionRecord.checkout(pool)
  File "/home/airflow/.local/lib/python3.7/site-packages/sqlalchemy/pool/base.py", line 493, in checkout
    rec = pool._do_get()
  File "/home/airflow/.local/lib/python3.7/site-packages/sqlalchemy/pool/impl.py", line 256, in _do_get
    return self._create_connection()
  File "/home/airflow/.local/lib/python3.7/site-packages/sqlalchemy/pool/base.py", line 273, in _create_connection
    return _ConnectionRecord(self)
  File "/home/airflow/.local/lib/python3.7/site-packages/sqlalchemy/pool/base.py", line 388, in __init__
    self.__connect()
  File "/home/airflow/.local/lib/python3.7/site-packages/sqlalchemy/pool/base.py", line 691, in __connect
    pool.logger.debug("Error on connect(): %s", e)
  File "/home/airflow/.local/lib/python3.7/site-packages/sqlalchemy/util/langhelpers.py", line 72, in __exit__
    with_traceback=exc_tb,
  File "/home/airflow/.local/lib/python3.7/site-packages/sqlalchemy/util/compat.py", line 211, in raise_
    raise exception
  File "/home/airflow/.local/lib/python3.7/site-packages/sqlalchemy/pool/base.py", line 686, in __connect
    self.dbapi_connection = connection = pool._invoke_creator(self)
  File "/home/airflow/.local/lib/python3.7/site-packages/sqlalchemy/engine/create.py", line 574, in connect
    return dialect.connect(*cargs, **cparams)
  File "/home/airflow/.local/lib/python3.7/site-packages/sqlalchemy/engine/default.py", line 598, in connect
    return self.dbapi.connect(*cargs, **cparams)
  File "/home/airflow/.local/lib/python3.7/site-packages/psycopg2/__init__.py", line 122, in connect
    conn = _connect(dsn, connection_factory=connection_factory, **kwasync)
sqlalchemy.exc.OperationalError: (psycopg2.OperationalError) could not translate host name "postgres" to address: Temporary failure in name resolution

(Background on this error at: https://sqlalche.me/e/14/e3q8)
[2024-10-28T21:51:09.350+0000] {task_command.py:410} INFO - Running <TaskInstance: api_binance_dag1.STRK manual__2024-10-28T21:50:17.159772+00:00 [running]> on host 3e776c2a96a1
[2024-10-28T21:51:11.535+0000] {taskinstance.py:1547} INFO - Exporting env vars: AIRFLOW_CTX_DAG_OWNER='Danil' AIRFLOW_CTX_DAG_ID='api_binance_dag1' AIRFLOW_CTX_TASK_ID='STRK' AIRFLOW_CTX_EXECUTION_DATE='2024-10-28T21:50:17.159772+00:00' AIRFLOW_CTX_TRY_NUMBER='1' AIRFLOW_CTX_DAG_RUN_ID='manual__2024-10-28T21:50:17.159772+00:00'
[2024-10-28T21:51:13.560+0000] {logging_mixin.py:149} INFO - Pushed to XCom: Key: STRK, Value: [[1729296000000, '0.40470000', '0.41490000', '0.39450000', '0.40810000', '19187123.72000000', 1729382399999, '7760997.42123500', 27942, '8668226.17000000', '3505243.29110500', '0'], [1729382400000, '0.40830000', '0.43800000', '0.39970000', '0.43380000', '37512625.92000000', 1729468799999, '15866723.02080800', 58823, '19438430.02000000', '8215487.21995900', '0'], [1729468800000, '0.43390000', '0.44160000', '0.41310000', '0.41580000', '37460095.85000000', 1729555199999, '15983296.79218100', 60529, '17255045.86000000', '7363577.39866700', '0'], [1729555200000, '0.41570000', '0.42720000', '0.40210000', '0.42270000', '31051244.68000000', 1729641599999, '12891255.24098400', 55095, '15187202.79000000', '6306911.49821200', '0'], [1729641600000, '0.42270000', '0.42570000', '0.38420000', '0.39970000', '37532161.00000000', 1729727999999, '15149839.06955100', 65835, '17318285.82000000', '6995512.18174600', '0'], [1729728000000, '0.39980000', '0.40980000', '0.39240000', '0.40140000', '27211990.18000000', 1729814399999, '10931170.62249900', 45529, '13307541.18000000', '5346924.82923200', '0'], [1729814400000, '0.40140000', '0.40520000', '0.34390000', '0.35990000', '40638236.54000000', 1729900799999, '15452328.66953500', 71367, '19428687.24000000', '7386391.58413300', '0'], [1729900800000, '0.35970000', '0.37280000', '0.35210000', '0.37030000', '34762947.22000000', 1729987199999, '12609289.86683300', 46767, '17799811.43000000', '6449884.70928300', '0'], [1729987200000, '0.37020000', '0.38640000', '0.36610000', '0.37860000', '15896715.97000000', 1730073599999, '5963579.49090000', 26694, '6626436.45000000', '2482519.78471000', '0'], [1730073600000, '0.37870000', '0.38490000', '0.36160000', '0.37990000', '27638839.61000000', 1730159999999, '10289800.93743200', 45352, '12928076.97000000', '4807413.16038400', '0']]
[2024-10-28T21:51:13.565+0000] {python.py:183} INFO - Done. Returned value was: None
[2024-10-28T21:51:13.589+0000] {taskinstance.py:1350} INFO - Marking task as SUCCESS. dag_id=api_binance_dag1, task_id=STRK, execution_date=20241028T215017, start_date=20241028T215032, end_date=20241028T215113
[2024-10-28T21:51:13.686+0000] {local_task_job_runner.py:225} INFO - Task exited with return code 0
[2024-10-28T21:51:13.854+0000] {taskinstance.py:2653} INFO - 0 downstream tasks scheduled from follow-on schedule check
