[2024-10-21T16:36:34.553+0000] {taskinstance.py:1103} INFO - Dependencies all met for dep_context=non-requeueable deps ti=<TaskInstance: api_binance_dag1.union_data_to_df manual__2024-10-21T16:28:31.446575+00:00 [queued]>
[2024-10-21T16:36:34.568+0000] {taskinstance.py:1103} INFO - Dependencies all met for dep_context=requeueable deps ti=<TaskInstance: api_binance_dag1.union_data_to_df manual__2024-10-21T16:28:31.446575+00:00 [queued]>
[2024-10-21T16:36:34.569+0000] {taskinstance.py:1308} INFO - Starting attempt 1 of 6
[2024-10-21T16:36:34.632+0000] {taskinstance.py:1327} INFO - Executing <Task(PythonOperator): union_data_to_df> on 2024-10-21 16:28:31.446575+00:00
[2024-10-21T16:36:34.660+0000] {standard_task_runner.py:57} INFO - Started process 477 to run task
[2024-10-21T16:36:34.667+0000] {standard_task_runner.py:84} INFO - Running: ['***', 'tasks', 'run', 'api_binance_dag1', 'union_data_to_df', 'manual__2024-10-21T16:28:31.446575+00:00', '--job-id', '397', '--raw', '--subdir', 'DAGS_FOLDER/binance.Dag1.py', '--cfg-path', '/tmp/tmppjja0qb2']
[2024-10-21T16:36:34.670+0000] {standard_task_runner.py:85} INFO - Job 397: Subtask union_data_to_df
[2024-10-21T16:36:34.694+0000] {warnings.py:110} WARNING - /home/***/.local/lib/python3.7/site-packages/***/settings.py:195: DeprecationWarning: The sql_alchemy_conn option in [core] has been moved to the sql_alchemy_conn option in [database] - the old setting has been used, but please update your config.
  SQL_ALCHEMY_CONN = conf.get("database", "SQL_ALCHEMY_CONN")

[2024-10-21T16:36:34.771+0000] {task_command.py:410} INFO - Running <TaskInstance: api_binance_dag1.union_data_to_df manual__2024-10-21T16:28:31.446575+00:00 [running]> on host 3e776c2a96a1
[2024-10-21T16:36:34.933+0000] {taskinstance.py:1547} INFO - Exporting env vars: AIRFLOW_CTX_DAG_OWNER='Danil' AIRFLOW_CTX_DAG_ID='api_binance_dag1' AIRFLOW_CTX_TASK_ID='union_data_to_df' AIRFLOW_CTX_EXECUTION_DATE='2024-10-21T16:28:31.446575+00:00' AIRFLOW_CTX_TRY_NUMBER='1' AIRFLOW_CTX_DAG_RUN_ID='manual__2024-10-21T16:28:31.446575+00:00'
[2024-10-21T16:36:35.033+0000] {taskinstance.py:1824} ERROR - Task failed with exception
Traceback (most recent call last):
  File "/home/airflow/.local/lib/python3.7/site-packages/pandas/core/indexes/base.py", line 3361, in get_loc
    return self._engine.get_loc(casted_key)
  File "pandas/_libs/index.pyx", line 76, in pandas._libs.index.IndexEngine.get_loc
  File "pandas/_libs/index.pyx", line 108, in pandas._libs.index.IndexEngine.get_loc
  File "pandas/_libs/hashtable_class_helper.pxi", line 5198, in pandas._libs.hashtable.PyObjectHashTable.get_item
  File "pandas/_libs/hashtable_class_helper.pxi", line 5206, in pandas._libs.hashtable.PyObjectHashTable.get_item
KeyError: 'Open Time'

The above exception was the direct cause of the following exception:

Traceback (most recent call last):
  File "/home/airflow/.local/lib/python3.7/site-packages/airflow/operators/python.py", line 181, in execute
    return_value = self.execute_callable()
  File "/home/airflow/.local/lib/python3.7/site-packages/airflow/operators/python.py", line 198, in execute_callable
    return self.python_callable(*self.op_args, **self.op_kwargs)
  File "/opt/airflow/dags/binance.Dag1.py", line 53, in push_from_xcom_to_df
    df['Дата открытия'] = pd.to_datetime(df['Open Time'], unit = 'ms')
  File "/home/airflow/.local/lib/python3.7/site-packages/pandas/core/frame.py", line 3458, in __getitem__
    indexer = self.columns.get_loc(key)
  File "/home/airflow/.local/lib/python3.7/site-packages/pandas/core/indexes/base.py", line 3363, in get_loc
    raise KeyError(key) from err
KeyError: 'Open Time'
[2024-10-21T16:36:35.058+0000] {taskinstance.py:1350} INFO - Marking task as UP_FOR_RETRY. dag_id=api_binance_dag1, task_id=union_data_to_df, execution_date=20241021T162831, start_date=20241021T163634, end_date=20241021T163635
[2024-10-21T16:36:35.089+0000] {standard_task_runner.py:109} ERROR - Failed to execute job 397 for task union_data_to_df ('Open Time'; 477)
[2024-10-21T16:36:35.120+0000] {local_task_job_runner.py:225} INFO - Task exited with return code 1
[2024-10-21T16:36:35.148+0000] {taskinstance.py:2653} INFO - 0 downstream tasks scheduled from follow-on schedule check
