[2024-10-28T11:45:12.125+0000] {taskinstance.py:1103} INFO - Dependencies all met for dep_context=non-requeueable deps ti=<TaskInstance: api_binance_dag1.SOL manual__2024-10-28T11:45:02.279614+00:00 [queued]>
[2024-10-28T11:45:12.168+0000] {taskinstance.py:1103} INFO - Dependencies all met for dep_context=requeueable deps ti=<TaskInstance: api_binance_dag1.SOL manual__2024-10-28T11:45:02.279614+00:00 [queued]>
[2024-10-28T11:45:12.169+0000] {taskinstance.py:1308} INFO - Starting attempt 1 of 3
[2024-10-28T11:45:12.216+0000] {taskinstance.py:1327} INFO - Executing <Task(PythonOperator): SOL> on 2024-10-28 11:45:02.279614+00:00
[2024-10-28T11:45:12.237+0000] {standard_task_runner.py:57} INFO - Started process 173 to run task
[2024-10-28T11:45:12.262+0000] {standard_task_runner.py:84} INFO - Running: ['***', 'tasks', 'run', 'api_binance_dag1', 'SOL', 'manual__2024-10-28T11:45:02.279614+00:00', '--job-id', '658', '--raw', '--subdir', 'DAGS_FOLDER/binance.Dag1.py', '--cfg-path', '/tmp/tmp61oxl6ij']
[2024-10-28T11:45:12.267+0000] {standard_task_runner.py:85} INFO - Job 658: Subtask SOL
[2024-10-28T11:45:12.318+0000] {warnings.py:110} WARNING - /home/***/.local/lib/python3.7/site-packages/***/settings.py:195: DeprecationWarning: The sql_alchemy_conn option in [core] has been moved to the sql_alchemy_conn option in [database] - the old setting has been used, but please update your config.
  SQL_ALCHEMY_CONN = conf.get("database", "SQL_ALCHEMY_CONN")

[2024-10-28T11:45:12.452+0000] {task_command.py:410} INFO - Running <TaskInstance: api_binance_dag1.SOL manual__2024-10-28T11:45:02.279614+00:00 [running]> on host 3e776c2a96a1
[2024-10-28T11:45:12.719+0000] {taskinstance.py:1547} INFO - Exporting env vars: AIRFLOW_CTX_DAG_OWNER='Danil' AIRFLOW_CTX_DAG_ID='api_binance_dag1' AIRFLOW_CTX_TASK_ID='SOL' AIRFLOW_CTX_EXECUTION_DATE='2024-10-28T11:45:02.279614+00:00' AIRFLOW_CTX_TRY_NUMBER='1' AIRFLOW_CTX_DAG_RUN_ID='manual__2024-10-28T11:45:02.279614+00:00'
[2024-10-28T11:45:25.381+0000] {taskinstance.py:1824} ERROR - Task failed with exception
Traceback (most recent call last):
  File "/home/airflow/.local/lib/python3.7/site-packages/urllib3/connection.py", line 175, in _new_conn
    (self._dns_host, self.port), self.timeout, **extra_kw
  File "/home/airflow/.local/lib/python3.7/site-packages/urllib3/util/connection.py", line 72, in create_connection
    for res in socket.getaddrinfo(host, port, family, socket.SOCK_STREAM):
  File "/usr/local/lib/python3.7/socket.py", line 752, in getaddrinfo
    for res in _socket.getaddrinfo(host, port, family, type, proto, flags):
socket.gaierror: [Errno -3] Temporary failure in name resolution

During handling of the above exception, another exception occurred:

Traceback (most recent call last):
  File "/home/airflow/.local/lib/python3.7/site-packages/urllib3/connectionpool.py", line 721, in urlopen
    chunked=chunked,
  File "/home/airflow/.local/lib/python3.7/site-packages/urllib3/connectionpool.py", line 403, in _make_request
    self._validate_conn(conn)
  File "/home/airflow/.local/lib/python3.7/site-packages/urllib3/connectionpool.py", line 1053, in _validate_conn
    conn.connect()
  File "/home/airflow/.local/lib/python3.7/site-packages/urllib3/connection.py", line 363, in connect
    self.sock = conn = self._new_conn()
  File "/home/airflow/.local/lib/python3.7/site-packages/urllib3/connection.py", line 187, in _new_conn
    self, "Failed to establish a new connection: %s" % e
urllib3.exceptions.NewConnectionError: <urllib3.connection.HTTPSConnection object at 0x7f2296b78d10>: Failed to establish a new connection: [Errno -3] Temporary failure in name resolution

During handling of the above exception, another exception occurred:

Traceback (most recent call last):
  File "/home/airflow/.local/lib/python3.7/site-packages/requests/adapters.py", line 497, in send
    chunked=chunked,
  File "/home/airflow/.local/lib/python3.7/site-packages/urllib3/connectionpool.py", line 799, in urlopen
    method, url, error=e, _pool=self, _stacktrace=sys.exc_info()[2]
  File "/home/airflow/.local/lib/python3.7/site-packages/urllib3/util/retry.py", line 592, in increment
    raise MaxRetryError(_pool, url, error or ResponseError(cause))
urllib3.exceptions.MaxRetryError: HTTPSConnectionPool(host='api.binance.com', port=443): Max retries exceeded with url: /api/v3/klines?symbol=SOLUSDT&interval=1d&startTime=1729251912724&endTime=1730115912724&limit=10 (Caused by NewConnectionError('<urllib3.connection.HTTPSConnection object at 0x7f2296b78d10>: Failed to establish a new connection: [Errno -3] Temporary failure in name resolution'))

During handling of the above exception, another exception occurred:

Traceback (most recent call last):
  File "/home/airflow/.local/lib/python3.7/site-packages/airflow/operators/python.py", line 181, in execute
    return_value = self.execute_callable()
  File "/home/airflow/.local/lib/python3.7/site-packages/airflow/operators/python.py", line 198, in execute_callable
    return self.python_callable(*self.op_args, **self.op_kwargs)
  File "/opt/airflow/dags/binance.Dag1.py", line 28, in pull_tokens_csv
    response = requests.get(url, params=params)
  File "/home/airflow/.local/lib/python3.7/site-packages/requests/api.py", line 73, in get
    return request("get", url, params=params, **kwargs)
  File "/home/airflow/.local/lib/python3.7/site-packages/requests/api.py", line 59, in request
    return session.request(method=method, url=url, **kwargs)
  File "/home/airflow/.local/lib/python3.7/site-packages/requests/sessions.py", line 589, in request
    resp = self.send(prep, **send_kwargs)
  File "/home/airflow/.local/lib/python3.7/site-packages/requests/sessions.py", line 703, in send
    r = adapter.send(request, **kwargs)
  File "/home/airflow/.local/lib/python3.7/site-packages/requests/adapters.py", line 519, in send
    raise ConnectionError(e, request=request)
requests.exceptions.ConnectionError: HTTPSConnectionPool(host='api.binance.com', port=443): Max retries exceeded with url: /api/v3/klines?symbol=SOLUSDT&interval=1d&startTime=1729251912724&endTime=1730115912724&limit=10 (Caused by NewConnectionError('<urllib3.connection.HTTPSConnection object at 0x7f2296b78d10>: Failed to establish a new connection: [Errno -3] Temporary failure in name resolution'))
[2024-10-28T11:45:27.002+0000] {taskinstance.py:1350} INFO - Marking task as UP_FOR_RETRY. dag_id=api_binance_dag1, task_id=SOL, execution_date=20241028T114502, start_date=20241028T114512, end_date=20241028T114526
[2024-10-28T11:45:27.095+0000] {standard_task_runner.py:109} ERROR - Failed to execute job 658 for task SOL (HTTPSConnectionPool(host='api.binance.com', port=443): Max retries exceeded with url: /api/v3/klines?symbol=SOLUSDT&interval=1d&startTime=1729251912724&endTime=1730115912724&limit=10 (Caused by NewConnectionError('<urllib3.connection.HTTPSConnection object at 0x7f2296b78d10>: Failed to establish a new connection: [Errno -3] Temporary failure in name resolution')); 173)
[2024-10-28T11:45:27.178+0000] {local_task_job_runner.py:225} INFO - Task exited with return code 1
[2024-10-28T11:45:27.272+0000] {taskinstance.py:2653} INFO - 0 downstream tasks scheduled from follow-on schedule check
