[2024-11-02T06:33:31.514+0000] {taskinstance.py:1103} INFO - Dependencies all met for dep_context=non-requeueable deps ti=<TaskInstance: api_binance_dag1.1INCH manual__2024-10-28T10:43:45.885498+00:00 [queued]>
[2024-11-02T06:33:31.555+0000] {taskinstance.py:1103} INFO - Dependencies all met for dep_context=requeueable deps ti=<TaskInstance: api_binance_dag1.1INCH manual__2024-10-28T10:43:45.885498+00:00 [queued]>
[2024-11-02T06:33:31.556+0000] {taskinstance.py:1308} INFO - Starting attempt 2 of 4
[2024-11-02T06:33:31.667+0000] {taskinstance.py:1327} INFO - Executing <Task(PythonOperator): 1INCH> on 2024-10-28 10:43:45.885498+00:00
[2024-11-02T06:33:31.692+0000] {standard_task_runner.py:57} INFO - Started process 133 to run task
[2024-11-02T06:33:31.712+0000] {standard_task_runner.py:84} INFO - Running: ['***', 'tasks', 'run', 'api_binance_dag1', '1INCH', 'manual__2024-10-28T10:43:45.885498+00:00', '--job-id', '867', '--raw', '--subdir', 'DAGS_FOLDER/binance.Dag1.py', '--cfg-path', '/tmp/tmpo7fvxxjn']
[2024-11-02T06:33:31.719+0000] {standard_task_runner.py:85} INFO - Job 867: Subtask 1INCH
[2024-11-02T06:33:31.785+0000] {warnings.py:110} WARNING - /home/***/.local/lib/python3.7/site-packages/***/settings.py:195: DeprecationWarning: The sql_alchemy_conn option in [core] has been moved to the sql_alchemy_conn option in [database] - the old setting has been used, but please update your config.
  SQL_ALCHEMY_CONN = conf.get("database", "SQL_ALCHEMY_CONN")

[2024-11-02T06:33:35.562+0000] {task_command.py:410} INFO - Running <TaskInstance: api_binance_dag1.1INCH manual__2024-10-28T10:43:45.885498+00:00 [running]> on host 3e776c2a96a1
[2024-11-02T06:33:47.210+0000] {job.py:216} ERROR - Job heartbeat got an exception
Traceback (most recent call last):
  File "/home/airflow/.local/lib/python3.7/site-packages/sqlalchemy/engine/base.py", line 3366, in _wrap_pool_connect
    return fn()
  File "/home/airflow/.local/lib/python3.7/site-packages/sqlalchemy/pool/base.py", line 327, in connect
    return _ConnectionFairy._checkout(self)
  File "/home/airflow/.local/lib/python3.7/site-packages/sqlalchemy/pool/base.py", line 894, in _checkout
    fairy = _ConnectionRecord.checkout(pool)
  File "/home/airflow/.local/lib/python3.7/site-packages/sqlalchemy/pool/base.py", line 493, in checkout
    rec = pool._do_get()
  File "/home/airflow/.local/lib/python3.7/site-packages/sqlalchemy/pool/impl.py", line 256, in _do_get
    return self._create_connection()
  File "/home/airflow/.local/lib/python3.7/site-packages/sqlalchemy/pool/base.py", line 273, in _create_connection
    return _ConnectionRecord(self)
  File "/home/airflow/.local/lib/python3.7/site-packages/sqlalchemy/pool/base.py", line 388, in __init__
    self.__connect()
  File "/home/airflow/.local/lib/python3.7/site-packages/sqlalchemy/pool/base.py", line 691, in __connect
    pool.logger.debug("Error on connect(): %s", e)
  File "/home/airflow/.local/lib/python3.7/site-packages/sqlalchemy/util/langhelpers.py", line 72, in __exit__
    with_traceback=exc_tb,
  File "/home/airflow/.local/lib/python3.7/site-packages/sqlalchemy/util/compat.py", line 211, in raise_
    raise exception
  File "/home/airflow/.local/lib/python3.7/site-packages/sqlalchemy/pool/base.py", line 686, in __connect
    self.dbapi_connection = connection = pool._invoke_creator(self)
  File "/home/airflow/.local/lib/python3.7/site-packages/sqlalchemy/engine/create.py", line 574, in connect
    return dialect.connect(*cargs, **cparams)
  File "/home/airflow/.local/lib/python3.7/site-packages/sqlalchemy/engine/default.py", line 598, in connect
    return self.dbapi.connect(*cargs, **cparams)
  File "/home/airflow/.local/lib/python3.7/site-packages/psycopg2/__init__.py", line 122, in connect
    conn = _connect(dsn, connection_factory=connection_factory, **kwasync)
psycopg2.OperationalError: could not translate host name "postgres" to address: Temporary failure in name resolution


The above exception was the direct cause of the following exception:

Traceback (most recent call last):
  File "/home/airflow/.local/lib/python3.7/site-packages/airflow/jobs/job.py", line 187, in heartbeat
    session.merge(self)
  File "/home/airflow/.local/lib/python3.7/site-packages/sqlalchemy/orm/session.py", line 3062, in merge
    _resolve_conflict_map=_resolve_conflict_map,
  File "/home/airflow/.local/lib/python3.7/site-packages/sqlalchemy/orm/session.py", line 3140, in _merge
    options=options,
  File "/home/airflow/.local/lib/python3.7/site-packages/sqlalchemy/orm/session.py", line 2861, in get
    execution_options=execution_options,
  File "/home/airflow/.local/lib/python3.7/site-packages/sqlalchemy/orm/session.py", line 2979, in _get_impl
    load_options=load_options,
  File "/home/airflow/.local/lib/python3.7/site-packages/sqlalchemy/orm/loading.py", line 534, in load_on_pk_identity
    bind_arguments=bind_arguments,
  File "/home/airflow/.local/lib/python3.7/site-packages/sqlalchemy/orm/session.py", line 1716, in execute
    conn = self._connection_for_bind(bind)
  File "/home/airflow/.local/lib/python3.7/site-packages/sqlalchemy/orm/session.py", line 1556, in _connection_for_bind
    engine, execution_options
  File "/home/airflow/.local/lib/python3.7/site-packages/sqlalchemy/orm/session.py", line 750, in _connection_for_bind
    conn = bind.connect()
  File "/home/airflow/.local/lib/python3.7/site-packages/sqlalchemy/engine/base.py", line 3320, in connect
    return self._connection_cls(self, close_with_result=close_with_result)
  File "/home/airflow/.local/lib/python3.7/site-packages/sqlalchemy/engine/base.py", line 96, in __init__
    else engine.raw_connection()
  File "/home/airflow/.local/lib/python3.7/site-packages/sqlalchemy/engine/base.py", line 3399, in raw_connection
    return self._wrap_pool_connect(self.pool.connect, _connection)
  File "/home/airflow/.local/lib/python3.7/site-packages/sqlalchemy/engine/base.py", line 3370, in _wrap_pool_connect
    e, dialect, self
  File "/home/airflow/.local/lib/python3.7/site-packages/sqlalchemy/engine/base.py", line 2204, in _handle_dbapi_exception_noconnection
    sqlalchemy_exception, with_traceback=exc_info[2], from_=e
  File "/home/airflow/.local/lib/python3.7/site-packages/sqlalchemy/util/compat.py", line 211, in raise_
    raise exception
  File "/home/airflow/.local/lib/python3.7/site-packages/sqlalchemy/engine/base.py", line 3366, in _wrap_pool_connect
    return fn()
  File "/home/airflow/.local/lib/python3.7/site-packages/sqlalchemy/pool/base.py", line 327, in connect
    return _ConnectionFairy._checkout(self)
  File "/home/airflow/.local/lib/python3.7/site-packages/sqlalchemy/pool/base.py", line 894, in _checkout
    fairy = _ConnectionRecord.checkout(pool)
  File "/home/airflow/.local/lib/python3.7/site-packages/sqlalchemy/pool/base.py", line 493, in checkout
    rec = pool._do_get()
  File "/home/airflow/.local/lib/python3.7/site-packages/sqlalchemy/pool/impl.py", line 256, in _do_get
    return self._create_connection()
  File "/home/airflow/.local/lib/python3.7/site-packages/sqlalchemy/pool/base.py", line 273, in _create_connection
    return _ConnectionRecord(self)
  File "/home/airflow/.local/lib/python3.7/site-packages/sqlalchemy/pool/base.py", line 388, in __init__
    self.__connect()
  File "/home/airflow/.local/lib/python3.7/site-packages/sqlalchemy/pool/base.py", line 691, in __connect
    pool.logger.debug("Error on connect(): %s", e)
  File "/home/airflow/.local/lib/python3.7/site-packages/sqlalchemy/util/langhelpers.py", line 72, in __exit__
    with_traceback=exc_tb,
  File "/home/airflow/.local/lib/python3.7/site-packages/sqlalchemy/util/compat.py", line 211, in raise_
    raise exception
  File "/home/airflow/.local/lib/python3.7/site-packages/sqlalchemy/pool/base.py", line 686, in __connect
    self.dbapi_connection = connection = pool._invoke_creator(self)
  File "/home/airflow/.local/lib/python3.7/site-packages/sqlalchemy/engine/create.py", line 574, in connect
    return dialect.connect(*cargs, **cparams)
  File "/home/airflow/.local/lib/python3.7/site-packages/sqlalchemy/engine/default.py", line 598, in connect
    return self.dbapi.connect(*cargs, **cparams)
  File "/home/airflow/.local/lib/python3.7/site-packages/psycopg2/__init__.py", line 122, in connect
    conn = _connect(dsn, connection_factory=connection_factory, **kwasync)
sqlalchemy.exc.OperationalError: (psycopg2.OperationalError) could not translate host name "postgres" to address: Temporary failure in name resolution

(Background on this error at: https://sqlalche.me/e/14/e3q8)
[2024-11-02T06:34:00.502+0000] {taskinstance.py:1547} INFO - Exporting env vars: AIRFLOW_CTX_DAG_OWNER='Danil' AIRFLOW_CTX_DAG_ID='api_binance_dag1' AIRFLOW_CTX_TASK_ID='1INCH' AIRFLOW_CTX_EXECUTION_DATE='2024-10-28T10:43:45.885498+00:00' AIRFLOW_CTX_TRY_NUMBER='2' AIRFLOW_CTX_DAG_RUN_ID='manual__2024-10-28T10:43:45.885498+00:00'
[2024-11-02T06:34:01.257+0000] {logging_mixin.py:149} INFO - Pushed to XCom: Key: 1INCH, Value: [[1729728000000, '0.26460000', '0.27740000', '0.26270000', '0.27430000', '7029755.00000000', 1729814399999, '1899047.28324000', 14586, '3628778.30000000', '982385.23081000', '0'], [1729814400000, '0.27450000', '0.27610000', '0.23950000', '0.24790000', '13013789.00000000', 1729900799999, '3382206.79497000', 26608, '5699538.90000000', '1474188.27339000', '0'], [1729900800000, '0.24780000', '0.25220000', '0.24230000', '0.25100000', '8356981.20000000', 1729987199999, '2073561.37707000', 19418, '4741741.90000000', '1176987.01890000', '0'], [1729987200000, '0.25100000', '0.26060000', '0.24990000', '0.25730000', '6926843.00000000', 1730073599999, '1767344.15877000', 13871, '3550207.90000000', '907081.87392000', '0'], [1730073600000, '0.25740000', '0.26130000', '0.24660000', '0.25920000', '11689792.50000000', 1730159999999, '2986429.59309000', 23239, '4606216.40000000', '1177459.45140000', '0'], [1730160000000, '0.25920000', '0.26840000', '0.25770000', '0.26410000', '10243619.40000000', 1730246399999, '2692355.47892000', 18689, '5234587.80000000', '1376403.80645000', '0'], [1730246400000, '0.26420000', '0.26430000', '0.25230000', '0.25980000', '10953210.80000000', 1730332799999, '2843748.39646000', 18467, '5844356.70000000', '1517238.89105000', '0'], [1730332800000, '0.25980000', '0.26030000', '0.24360000', '0.24600000', '7209692.50000000', 1730419199999, '1812709.45005000', 13236, '3414328.90000000', '858198.92987000', '0'], [1730419200000, '0.24590000', '0.25060000', '0.23930000', '0.24380000', '6208641.50000000', 1730505599999, '1514563.09852000', 12275, '2945205.70000000', '718476.91438000', '0'], [1730505600000, '0.24380000', '0.24780000', '0.24270000', '0.24400000', '817531.30000000', 1730591999999, '200220.00026000', 1967, '408883.10000000', '100218.37439000', '0']]
[2024-11-02T06:34:01.261+0000] {python.py:183} INFO - Done. Returned value was: None
[2024-11-02T06:34:01.293+0000] {taskinstance.py:1350} INFO - Marking task as SUCCESS. dag_id=api_binance_dag1, task_id=1INCH, execution_date=20241028T104345, start_date=20241102T063331, end_date=20241102T063401
[2024-11-02T06:34:01.383+0000] {local_task_job_runner.py:225} INFO - Task exited with return code 0
[2024-11-02T06:34:01.469+0000] {taskinstance.py:2653} INFO - 0 downstream tasks scheduled from follow-on schedule check
