[2024-11-04T17:49:32.216+0000] {warnings.py:110} WARNING - /home/***/.local/lib/python3.7/site-packages/***/utils/sqlalchemy.py:124: DeprecationWarning: The sql_alchemy_conn option in [core] has been moved to the sql_alchemy_conn option in [database] - the old setting has been used, but please update your config.
  return not conf.get("database", "sql_alchemy_conn").startswith("mssql")

[2024-11-04T17:49:32.398+0000] {taskinstance.py:1103} INFO - Dependencies all met for dep_context=non-requeueable deps ti=<TaskInstance: api_binance_dag1.TON scheduled__2024-11-03T09:00:00+00:00 [queued]>
[2024-11-04T17:49:32.422+0000] {taskinstance.py:1103} INFO - Dependencies all met for dep_context=requeueable deps ti=<TaskInstance: api_binance_dag1.TON scheduled__2024-11-03T09:00:00+00:00 [queued]>
[2024-11-04T17:49:32.424+0000] {taskinstance.py:1308} INFO - Starting attempt 1 of 3
[2024-11-04T17:49:32.477+0000] {taskinstance.py:1327} INFO - Executing <Task(PythonOperator): TON> on 2024-11-03 09:00:00+00:00
[2024-11-04T17:49:32.500+0000] {standard_task_runner.py:57} INFO - Started process 70 to run task
[2024-11-04T17:49:32.518+0000] {standard_task_runner.py:84} INFO - Running: ['***', 'tasks', 'run', 'api_binance_dag1', 'TON', 'scheduled__2024-11-03T09:00:00+00:00', '--job-id', '986', '--raw', '--subdir', 'DAGS_FOLDER/binance.Dag1.py', '--cfg-path', '/tmp/tmpigqqd7x4']
[2024-11-04T17:49:32.529+0000] {standard_task_runner.py:85} INFO - Job 986: Subtask TON
[2024-11-04T17:49:32.591+0000] {warnings.py:110} WARNING - /home/***/.local/lib/python3.7/site-packages/***/settings.py:195: DeprecationWarning: The sql_alchemy_conn option in [core] has been moved to the sql_alchemy_conn option in [database] - the old setting has been used, but please update your config.
  SQL_ALCHEMY_CONN = conf.get("database", "SQL_ALCHEMY_CONN")

[2024-11-04T17:49:32.778+0000] {task_command.py:410} INFO - Running <TaskInstance: api_binance_dag1.TON scheduled__2024-11-03T09:00:00+00:00 [running]> on host 3e776c2a96a1
[2024-11-04T17:49:32.836+0000] {warnings.py:110} WARNING - /home/***/.local/lib/python3.7/site-packages/***/utils/sqlalchemy.py:124: DeprecationWarning: The sql_alchemy_conn option in [core] has been moved to the sql_alchemy_conn option in [database] - the old setting has been used, but please update your config.
  return not conf.get("database", "sql_alchemy_conn").startswith("mssql")

[2024-11-04T17:49:43.419+0000] {taskinstance.py:1547} INFO - Exporting env vars: AIRFLOW_CTX_DAG_OWNER='Danil' AIRFLOW_CTX_DAG_ID='api_binance_dag1' AIRFLOW_CTX_TASK_ID='TON' AIRFLOW_CTX_EXECUTION_DATE='2024-11-03T09:00:00+00:00' AIRFLOW_CTX_TRY_NUMBER='1' AIRFLOW_CTX_DAG_RUN_ID='scheduled__2024-11-03T09:00:00+00:00'
[2024-11-04T17:49:58.680+0000] {job.py:216} ERROR - Job heartbeat got an exception
Traceback (most recent call last):
  File "/home/airflow/.local/lib/python3.7/site-packages/sqlalchemy/engine/base.py", line 3366, in _wrap_pool_connect
    return fn()
  File "/home/airflow/.local/lib/python3.7/site-packages/sqlalchemy/pool/base.py", line 327, in connect
    return _ConnectionFairy._checkout(self)
  File "/home/airflow/.local/lib/python3.7/site-packages/sqlalchemy/pool/base.py", line 894, in _checkout
    fairy = _ConnectionRecord.checkout(pool)
  File "/home/airflow/.local/lib/python3.7/site-packages/sqlalchemy/pool/base.py", line 493, in checkout
    rec = pool._do_get()
  File "/home/airflow/.local/lib/python3.7/site-packages/sqlalchemy/pool/impl.py", line 256, in _do_get
    return self._create_connection()
  File "/home/airflow/.local/lib/python3.7/site-packages/sqlalchemy/pool/base.py", line 273, in _create_connection
    return _ConnectionRecord(self)
  File "/home/airflow/.local/lib/python3.7/site-packages/sqlalchemy/pool/base.py", line 388, in __init__
    self.__connect()
  File "/home/airflow/.local/lib/python3.7/site-packages/sqlalchemy/pool/base.py", line 691, in __connect
    pool.logger.debug("Error on connect(): %s", e)
  File "/home/airflow/.local/lib/python3.7/site-packages/sqlalchemy/util/langhelpers.py", line 72, in __exit__
    with_traceback=exc_tb,
  File "/home/airflow/.local/lib/python3.7/site-packages/sqlalchemy/util/compat.py", line 211, in raise_
    raise exception
  File "/home/airflow/.local/lib/python3.7/site-packages/sqlalchemy/pool/base.py", line 686, in __connect
    self.dbapi_connection = connection = pool._invoke_creator(self)
  File "/home/airflow/.local/lib/python3.7/site-packages/sqlalchemy/engine/create.py", line 574, in connect
    return dialect.connect(*cargs, **cparams)
  File "/home/airflow/.local/lib/python3.7/site-packages/sqlalchemy/engine/default.py", line 598, in connect
    return self.dbapi.connect(*cargs, **cparams)
  File "/home/airflow/.local/lib/python3.7/site-packages/psycopg2/__init__.py", line 122, in connect
    conn = _connect(dsn, connection_factory=connection_factory, **kwasync)
psycopg2.OperationalError: could not translate host name "postgres" to address: Temporary failure in name resolution


The above exception was the direct cause of the following exception:

Traceback (most recent call last):
  File "/home/airflow/.local/lib/python3.7/site-packages/airflow/jobs/job.py", line 187, in heartbeat
    session.merge(self)
  File "/home/airflow/.local/lib/python3.7/site-packages/sqlalchemy/orm/session.py", line 3062, in merge
    _resolve_conflict_map=_resolve_conflict_map,
  File "/home/airflow/.local/lib/python3.7/site-packages/sqlalchemy/orm/session.py", line 3140, in _merge
    options=options,
  File "/home/airflow/.local/lib/python3.7/site-packages/sqlalchemy/orm/session.py", line 2861, in get
    execution_options=execution_options,
  File "/home/airflow/.local/lib/python3.7/site-packages/sqlalchemy/orm/session.py", line 2979, in _get_impl
    load_options=load_options,
  File "/home/airflow/.local/lib/python3.7/site-packages/sqlalchemy/orm/loading.py", line 534, in load_on_pk_identity
    bind_arguments=bind_arguments,
  File "/home/airflow/.local/lib/python3.7/site-packages/sqlalchemy/orm/session.py", line 1716, in execute
    conn = self._connection_for_bind(bind)
  File "/home/airflow/.local/lib/python3.7/site-packages/sqlalchemy/orm/session.py", line 1556, in _connection_for_bind
    engine, execution_options
  File "/home/airflow/.local/lib/python3.7/site-packages/sqlalchemy/orm/session.py", line 750, in _connection_for_bind
    conn = bind.connect()
  File "/home/airflow/.local/lib/python3.7/site-packages/sqlalchemy/engine/base.py", line 3320, in connect
    return self._connection_cls(self, close_with_result=close_with_result)
  File "/home/airflow/.local/lib/python3.7/site-packages/sqlalchemy/engine/base.py", line 96, in __init__
    else engine.raw_connection()
  File "/home/airflow/.local/lib/python3.7/site-packages/sqlalchemy/engine/base.py", line 3399, in raw_connection
    return self._wrap_pool_connect(self.pool.connect, _connection)
  File "/home/airflow/.local/lib/python3.7/site-packages/sqlalchemy/engine/base.py", line 3370, in _wrap_pool_connect
    e, dialect, self
  File "/home/airflow/.local/lib/python3.7/site-packages/sqlalchemy/engine/base.py", line 2204, in _handle_dbapi_exception_noconnection
    sqlalchemy_exception, with_traceback=exc_info[2], from_=e
  File "/home/airflow/.local/lib/python3.7/site-packages/sqlalchemy/util/compat.py", line 211, in raise_
    raise exception
  File "/home/airflow/.local/lib/python3.7/site-packages/sqlalchemy/engine/base.py", line 3366, in _wrap_pool_connect
    return fn()
  File "/home/airflow/.local/lib/python3.7/site-packages/sqlalchemy/pool/base.py", line 327, in connect
    return _ConnectionFairy._checkout(self)
  File "/home/airflow/.local/lib/python3.7/site-packages/sqlalchemy/pool/base.py", line 894, in _checkout
    fairy = _ConnectionRecord.checkout(pool)
  File "/home/airflow/.local/lib/python3.7/site-packages/sqlalchemy/pool/base.py", line 493, in checkout
    rec = pool._do_get()
  File "/home/airflow/.local/lib/python3.7/site-packages/sqlalchemy/pool/impl.py", line 256, in _do_get
    return self._create_connection()
  File "/home/airflow/.local/lib/python3.7/site-packages/sqlalchemy/pool/base.py", line 273, in _create_connection
    return _ConnectionRecord(self)
  File "/home/airflow/.local/lib/python3.7/site-packages/sqlalchemy/pool/base.py", line 388, in __init__
    self.__connect()
  File "/home/airflow/.local/lib/python3.7/site-packages/sqlalchemy/pool/base.py", line 691, in __connect
    pool.logger.debug("Error on connect(): %s", e)
  File "/home/airflow/.local/lib/python3.7/site-packages/sqlalchemy/util/langhelpers.py", line 72, in __exit__
    with_traceback=exc_tb,
  File "/home/airflow/.local/lib/python3.7/site-packages/sqlalchemy/util/compat.py", line 211, in raise_
    raise exception
  File "/home/airflow/.local/lib/python3.7/site-packages/sqlalchemy/pool/base.py", line 686, in __connect
    self.dbapi_connection = connection = pool._invoke_creator(self)
  File "/home/airflow/.local/lib/python3.7/site-packages/sqlalchemy/engine/create.py", line 574, in connect
    return dialect.connect(*cargs, **cparams)
  File "/home/airflow/.local/lib/python3.7/site-packages/sqlalchemy/engine/default.py", line 598, in connect
    return self.dbapi.connect(*cargs, **cparams)
  File "/home/airflow/.local/lib/python3.7/site-packages/psycopg2/__init__.py", line 122, in connect
    conn = _connect(dsn, connection_factory=connection_factory, **kwasync)
sqlalchemy.exc.OperationalError: (psycopg2.OperationalError) could not translate host name "postgres" to address: Temporary failure in name resolution

(Background on this error at: https://sqlalche.me/e/14/e3q8)
[2024-11-04T17:50:02.480+0000] {logging_mixin.py:149} INFO - Pushed to XCom: Key: TON, Value: [[1729900800000, '4.77600000', '5.00000000', '4.73800000', '4.92500000', '5068582.59000000', 1729987199999, '24802266.82312000', 254797, '2354209.37000000', '11515004.77707000', '0'], [1729987200000, '4.92400000', '4.99800000', '4.90400000', '4.99700000', '2461684.22000000', 1730073599999, '12157796.03253000', 135651, '1153116.36000000', '5694670.06633000', '0'], [1730073600000, '4.99700000', '5.05400000', '4.92700000', '5.01700000', '4523486.50000000', 1730159999999, '22583295.68516000', 263603, '2406685.78000000', '12010827.46181000', '0'], [1730160000000, '5.01700000', '5.14700000', '4.98700000', '5.02000000', '6462665.04000000', 1730246399999, '32642895.46710000', 260510, '3699417.03000000', '18680525.06409000', '0'], [1730246400000, '5.02000000', '5.08100000', '4.95900000', '4.98900000', '6779061.42000000', 1730332799999, '33990781.48751000', 264376, '3595811.94000000', '18033305.59764000', '0'], [1730332800000, '4.99000000', '5.00800000', '4.75800000', '4.84600000', '5458005.45000000', 1730419199999, '26586945.72310000', 261843, '2789390.52000000', '13574736.74275000', '0'], [1730419200000, '4.84700000', '4.95100000', '4.79100000', '4.89400000', '4528128.74000000', 1730505599999, '22113893.00538000', 272871, '2204588.16000000', '10760961.59991000', '0'], [1730505600000, '4.89400000', '4.96200000', '4.84500000', '4.87400000', '2248134.00000000', 1730591999999, '11027003.20994000', 151010, '1114659.68000000', '5464229.80504000', '0'], [1730592000000, '4.87400000', '4.88400000', '4.66400000', '4.81800000', '4335200.82000000', 1730678399999, '20692480.21508000', 278656, '2213858.57000000', '10561236.42092000', '0'], [1730678400000, '4.81800000', '4.90900000', '4.74600000', '4.78700000', '2362148.78000000', 1730764799999, '11417756.14612000', 181059, '1274857.33000000', '6160434.62508000', '0']]
[2024-11-04T17:50:02.503+0000] {python.py:183} INFO - Done. Returned value was: None
[2024-11-04T17:50:02.721+0000] {taskinstance.py:1350} INFO - Marking task as SUCCESS. dag_id=api_binance_dag1, task_id=TON, execution_date=20241103T090000, start_date=20241104T174932, end_date=20241104T175002
[2024-11-04T17:50:03.023+0000] {local_task_job_runner.py:225} INFO - Task exited with return code 0
[2024-11-04T17:50:03.104+0000] {taskinstance.py:2653} INFO - 0 downstream tasks scheduled from follow-on schedule check
