[2024-10-16T18:10:41.164+0000] {warnings.py:110} WARNING - /home/***/.local/lib/python3.7/site-packages/***/utils/sqlalchemy.py:124: DeprecationWarning: The sql_alchemy_conn option in [core] has been moved to the sql_alchemy_conn option in [database] - the old setting has been used, but please update your config.
  return not conf.get("database", "sql_alchemy_conn").startswith("mssql")

[2024-10-16T18:10:44.417+0000] {taskinstance.py:1103} INFO - Dependencies all met for dep_context=non-requeueable deps ti=<TaskInstance: api_binance_dag1.STRK scheduled__2024-10-08T09:00:00+00:00 [queued]>
[2024-10-16T18:10:44.480+0000] {taskinstance.py:1103} INFO - Dependencies all met for dep_context=requeueable deps ti=<TaskInstance: api_binance_dag1.STRK scheduled__2024-10-08T09:00:00+00:00 [queued]>
[2024-10-16T18:10:44.489+0000] {taskinstance.py:1308} INFO - Starting attempt 3 of 6
[2024-10-16T18:10:44.820+0000] {taskinstance.py:1327} INFO - Executing <Task(PythonOperator): STRK> on 2024-10-08 09:00:00+00:00
[2024-10-16T18:10:44.911+0000] {standard_task_runner.py:57} INFO - Started process 75 to run task
[2024-10-16T18:10:45.028+0000] {standard_task_runner.py:84} INFO - Running: ['***', 'tasks', 'run', 'api_binance_dag1', 'STRK', 'scheduled__2024-10-08T09:00:00+00:00', '--job-id', '217', '--raw', '--subdir', 'DAGS_FOLDER/binance.Dag1.py', '--cfg-path', '/tmp/tmpcdp__x7m']
[2024-10-16T18:10:45.047+0000] {standard_task_runner.py:85} INFO - Job 217: Subtask STRK
[2024-10-16T18:10:47.036+0000] {warnings.py:110} WARNING - /home/***/.local/lib/python3.7/site-packages/***/settings.py:195: DeprecationWarning: The sql_alchemy_conn option in [core] has been moved to the sql_alchemy_conn option in [database] - the old setting has been used, but please update your config.
  SQL_ALCHEMY_CONN = conf.get("database", "SQL_ALCHEMY_CONN")

[2024-10-16T18:10:48.281+0000] {task_command.py:410} INFO - Running <TaskInstance: api_binance_dag1.STRK scheduled__2024-10-08T09:00:00+00:00 [running]> on host 3e776c2a96a1
[2024-10-16T18:10:48.338+0000] {warnings.py:110} WARNING - /home/***/.local/lib/python3.7/site-packages/***/utils/sqlalchemy.py:124: DeprecationWarning: The sql_alchemy_conn option in [core] has been moved to the sql_alchemy_conn option in [database] - the old setting has been used, but please update your config.
  return not conf.get("database", "sql_alchemy_conn").startswith("mssql")

[2024-10-16T18:10:52.577+0000] {taskinstance.py:1547} INFO - Exporting env vars: AIRFLOW_CTX_DAG_OWNER='Danil' AIRFLOW_CTX_DAG_ID='api_binance_dag1' AIRFLOW_CTX_TASK_ID='STRK' AIRFLOW_CTX_EXECUTION_DATE='2024-10-08T09:00:00+00:00' AIRFLOW_CTX_TRY_NUMBER='3' AIRFLOW_CTX_DAG_RUN_ID='scheduled__2024-10-08T09:00:00+00:00'
[2024-10-16T18:11:12.978+0000] {taskinstance.py:1824} ERROR - Task failed with exception
Traceback (most recent call last):
  File "/home/airflow/.local/lib/python3.7/site-packages/urllib3/connection.py", line 175, in _new_conn
    (self._dns_host, self.port), self.timeout, **extra_kw
  File "/home/airflow/.local/lib/python3.7/site-packages/urllib3/util/connection.py", line 72, in create_connection
    for res in socket.getaddrinfo(host, port, family, socket.SOCK_STREAM):
  File "/usr/local/lib/python3.7/socket.py", line 752, in getaddrinfo
    for res in _socket.getaddrinfo(host, port, family, type, proto, flags):
socket.gaierror: [Errno -3] Temporary failure in name resolution

During handling of the above exception, another exception occurred:

Traceback (most recent call last):
  File "/home/airflow/.local/lib/python3.7/site-packages/urllib3/connectionpool.py", line 721, in urlopen
    chunked=chunked,
  File "/home/airflow/.local/lib/python3.7/site-packages/urllib3/connectionpool.py", line 403, in _make_request
    self._validate_conn(conn)
  File "/home/airflow/.local/lib/python3.7/site-packages/urllib3/connectionpool.py", line 1053, in _validate_conn
    conn.connect()
  File "/home/airflow/.local/lib/python3.7/site-packages/urllib3/connection.py", line 363, in connect
    self.sock = conn = self._new_conn()
  File "/home/airflow/.local/lib/python3.7/site-packages/urllib3/connection.py", line 187, in _new_conn
    self, "Failed to establish a new connection: %s" % e
urllib3.exceptions.NewConnectionError: <urllib3.connection.HTTPSConnection object at 0x7fb7620115d0>: Failed to establish a new connection: [Errno -3] Temporary failure in name resolution

During handling of the above exception, another exception occurred:

Traceback (most recent call last):
  File "/home/airflow/.local/lib/python3.7/site-packages/requests/adapters.py", line 497, in send
    chunked=chunked,
  File "/home/airflow/.local/lib/python3.7/site-packages/urllib3/connectionpool.py", line 799, in urlopen
    method, url, error=e, _pool=self, _stacktrace=sys.exc_info()[2]
  File "/home/airflow/.local/lib/python3.7/site-packages/urllib3/util/retry.py", line 592, in increment
    raise MaxRetryError(_pool, url, error or ResponseError(cause))
urllib3.exceptions.MaxRetryError: HTTPSConnectionPool(host='api.binance.com', port=443): Max retries exceeded with url: /api/v3/klines?symbol=STRKUSDT&interval=1d&startTime=1728238252617&endTime=1729102252617&limit=7 (Caused by NewConnectionError('<urllib3.connection.HTTPSConnection object at 0x7fb7620115d0>: Failed to establish a new connection: [Errno -3] Temporary failure in name resolution'))

During handling of the above exception, another exception occurred:

Traceback (most recent call last):
  File "/home/airflow/.local/lib/python3.7/site-packages/airflow/operators/python.py", line 181, in execute
    return_value = self.execute_callable()
  File "/home/airflow/.local/lib/python3.7/site-packages/airflow/operators/python.py", line 198, in execute_callable
    return self.python_callable(*self.op_args, **self.op_kwargs)
  File "/opt/airflow/dags/binance.Dag1.py", line 38, in pull_tokens_csv
    response: str = requests.get(url, params=params)
  File "/home/airflow/.local/lib/python3.7/site-packages/requests/api.py", line 73, in get
    return request("get", url, params=params, **kwargs)
  File "/home/airflow/.local/lib/python3.7/site-packages/requests/api.py", line 59, in request
    return session.request(method=method, url=url, **kwargs)
  File "/home/airflow/.local/lib/python3.7/site-packages/requests/sessions.py", line 589, in request
    resp = self.send(prep, **send_kwargs)
  File "/home/airflow/.local/lib/python3.7/site-packages/requests/sessions.py", line 703, in send
    r = adapter.send(request, **kwargs)
  File "/home/airflow/.local/lib/python3.7/site-packages/requests/adapters.py", line 519, in send
    raise ConnectionError(e, request=request)
requests.exceptions.ConnectionError: HTTPSConnectionPool(host='api.binance.com', port=443): Max retries exceeded with url: /api/v3/klines?symbol=STRKUSDT&interval=1d&startTime=1728238252617&endTime=1729102252617&limit=7 (Caused by NewConnectionError('<urllib3.connection.HTTPSConnection object at 0x7fb7620115d0>: Failed to establish a new connection: [Errno -3] Temporary failure in name resolution'))
[2024-10-16T18:11:17.896+0000] {taskinstance.py:1350} INFO - Marking task as UP_FOR_RETRY. dag_id=api_binance_dag1, task_id=STRK, execution_date=20241008T090000, start_date=20241016T181044, end_date=20241016T181117
[2024-10-16T18:11:18.031+0000] {standard_task_runner.py:109} ERROR - Failed to execute job 217 for task STRK (HTTPSConnectionPool(host='api.binance.com', port=443): Max retries exceeded with url: /api/v3/klines?symbol=STRKUSDT&interval=1d&startTime=1728238252617&endTime=1729102252617&limit=7 (Caused by NewConnectionError('<urllib3.connection.HTTPSConnection object at 0x7fb7620115d0>: Failed to establish a new connection: [Errno -3] Temporary failure in name resolution')); 75)
[2024-10-16T18:11:18.108+0000] {local_task_job_runner.py:225} INFO - Task exited with return code 1
[2024-10-16T18:11:18.286+0000] {taskinstance.py:2653} INFO - 0 downstream tasks scheduled from follow-on schedule check
