[2024-10-16T18:10:41.240+0000] {warnings.py:110} WARNING - /home/***/.local/lib/python3.7/site-packages/***/utils/sqlalchemy.py:124: DeprecationWarning: The sql_alchemy_conn option in [core] has been moved to the sql_alchemy_conn option in [database] - the old setting has been used, but please update your config.
  return not conf.get("database", "sql_alchemy_conn").startswith("mssql")

[2024-10-16T18:10:47.541+0000] {taskinstance.py:1103} INFO - Dependencies all met for dep_context=non-requeueable deps ti=<TaskInstance: api_binance_dag1.SUI scheduled__2024-10-14T09:00:00+00:00 [queued]>
[2024-10-16T18:10:49.459+0000] {taskinstance.py:1103} INFO - Dependencies all met for dep_context=requeueable deps ti=<TaskInstance: api_binance_dag1.SUI scheduled__2024-10-14T09:00:00+00:00 [queued]>
[2024-10-16T18:10:49.460+0000] {taskinstance.py:1308} INFO - Starting attempt 3 of 6
[2024-10-16T18:10:49.541+0000] {taskinstance.py:1327} INFO - Executing <Task(PythonOperator): SUI> on 2024-10-14 09:00:00+00:00
[2024-10-16T18:10:49.577+0000] {standard_task_runner.py:57} INFO - Started process 76 to run task
[2024-10-16T18:10:49.660+0000] {standard_task_runner.py:84} INFO - Running: ['***', 'tasks', 'run', 'api_binance_dag1', 'SUI', 'scheduled__2024-10-14T09:00:00+00:00', '--job-id', '219', '--raw', '--subdir', 'DAGS_FOLDER/binance.Dag1.py', '--cfg-path', '/tmp/tmpl0laccq7']
[2024-10-16T18:10:49.681+0000] {standard_task_runner.py:85} INFO - Job 219: Subtask SUI
[2024-10-16T18:10:52.021+0000] {warnings.py:110} WARNING - /home/***/.local/lib/python3.7/site-packages/***/settings.py:195: DeprecationWarning: The sql_alchemy_conn option in [core] has been moved to the sql_alchemy_conn option in [database] - the old setting has been used, but please update your config.
  SQL_ALCHEMY_CONN = conf.get("database", "SQL_ALCHEMY_CONN")

[2024-10-16T18:10:59.906+0000] {task_command.py:410} INFO - Running <TaskInstance: api_binance_dag1.SUI scheduled__2024-10-14T09:00:00+00:00 [running]> on host 3e776c2a96a1
[2024-10-16T18:11:00.342+0000] {warnings.py:110} WARNING - /home/***/.local/lib/python3.7/site-packages/***/utils/sqlalchemy.py:124: DeprecationWarning: The sql_alchemy_conn option in [core] has been moved to the sql_alchemy_conn option in [database] - the old setting has been used, but please update your config.
  return not conf.get("database", "sql_alchemy_conn").startswith("mssql")

[2024-10-16T18:11:01.152+0000] {taskinstance.py:1547} INFO - Exporting env vars: AIRFLOW_CTX_DAG_OWNER='Danil' AIRFLOW_CTX_DAG_ID='api_binance_dag1' AIRFLOW_CTX_TASK_ID='SUI' AIRFLOW_CTX_EXECUTION_DATE='2024-10-14T09:00:00+00:00' AIRFLOW_CTX_TRY_NUMBER='3' AIRFLOW_CTX_DAG_RUN_ID='scheduled__2024-10-14T09:00:00+00:00'
[2024-10-16T18:11:35.628+0000] {job.py:216} ERROR - Job heartbeat got an exception
Traceback (most recent call last):
  File "/home/airflow/.local/lib/python3.7/site-packages/sqlalchemy/engine/base.py", line 3366, in _wrap_pool_connect
    return fn()
  File "/home/airflow/.local/lib/python3.7/site-packages/sqlalchemy/pool/base.py", line 327, in connect
    return _ConnectionFairy._checkout(self)
  File "/home/airflow/.local/lib/python3.7/site-packages/sqlalchemy/pool/base.py", line 894, in _checkout
    fairy = _ConnectionRecord.checkout(pool)
  File "/home/airflow/.local/lib/python3.7/site-packages/sqlalchemy/pool/base.py", line 493, in checkout
    rec = pool._do_get()
  File "/home/airflow/.local/lib/python3.7/site-packages/sqlalchemy/pool/impl.py", line 256, in _do_get
    return self._create_connection()
  File "/home/airflow/.local/lib/python3.7/site-packages/sqlalchemy/pool/base.py", line 273, in _create_connection
    return _ConnectionRecord(self)
  File "/home/airflow/.local/lib/python3.7/site-packages/sqlalchemy/pool/base.py", line 388, in __init__
    self.__connect()
  File "/home/airflow/.local/lib/python3.7/site-packages/sqlalchemy/pool/base.py", line 691, in __connect
    pool.logger.debug("Error on connect(): %s", e)
  File "/home/airflow/.local/lib/python3.7/site-packages/sqlalchemy/util/langhelpers.py", line 72, in __exit__
    with_traceback=exc_tb,
  File "/home/airflow/.local/lib/python3.7/site-packages/sqlalchemy/util/compat.py", line 211, in raise_
    raise exception
  File "/home/airflow/.local/lib/python3.7/site-packages/sqlalchemy/pool/base.py", line 686, in __connect
    self.dbapi_connection = connection = pool._invoke_creator(self)
  File "/home/airflow/.local/lib/python3.7/site-packages/sqlalchemy/engine/create.py", line 574, in connect
    return dialect.connect(*cargs, **cparams)
  File "/home/airflow/.local/lib/python3.7/site-packages/sqlalchemy/engine/default.py", line 598, in connect
    return self.dbapi.connect(*cargs, **cparams)
  File "/home/airflow/.local/lib/python3.7/site-packages/psycopg2/__init__.py", line 122, in connect
    conn = _connect(dsn, connection_factory=connection_factory, **kwasync)
psycopg2.OperationalError: could not translate host name "postgres" to address: Temporary failure in name resolution


The above exception was the direct cause of the following exception:

Traceback (most recent call last):
  File "/home/airflow/.local/lib/python3.7/site-packages/airflow/jobs/job.py", line 187, in heartbeat
    session.merge(self)
  File "/home/airflow/.local/lib/python3.7/site-packages/sqlalchemy/orm/session.py", line 3062, in merge
    _resolve_conflict_map=_resolve_conflict_map,
  File "/home/airflow/.local/lib/python3.7/site-packages/sqlalchemy/orm/session.py", line 3140, in _merge
    options=options,
  File "/home/airflow/.local/lib/python3.7/site-packages/sqlalchemy/orm/session.py", line 2861, in get
    execution_options=execution_options,
  File "/home/airflow/.local/lib/python3.7/site-packages/sqlalchemy/orm/session.py", line 2979, in _get_impl
    load_options=load_options,
  File "/home/airflow/.local/lib/python3.7/site-packages/sqlalchemy/orm/loading.py", line 534, in load_on_pk_identity
    bind_arguments=bind_arguments,
  File "/home/airflow/.local/lib/python3.7/site-packages/sqlalchemy/orm/session.py", line 1716, in execute
    conn = self._connection_for_bind(bind)
  File "/home/airflow/.local/lib/python3.7/site-packages/sqlalchemy/orm/session.py", line 1556, in _connection_for_bind
    engine, execution_options
  File "/home/airflow/.local/lib/python3.7/site-packages/sqlalchemy/orm/session.py", line 750, in _connection_for_bind
    conn = bind.connect()
  File "/home/airflow/.local/lib/python3.7/site-packages/sqlalchemy/engine/base.py", line 3320, in connect
    return self._connection_cls(self, close_with_result=close_with_result)
  File "/home/airflow/.local/lib/python3.7/site-packages/sqlalchemy/engine/base.py", line 96, in __init__
    else engine.raw_connection()
  File "/home/airflow/.local/lib/python3.7/site-packages/sqlalchemy/engine/base.py", line 3399, in raw_connection
    return self._wrap_pool_connect(self.pool.connect, _connection)
  File "/home/airflow/.local/lib/python3.7/site-packages/sqlalchemy/engine/base.py", line 3370, in _wrap_pool_connect
    e, dialect, self
  File "/home/airflow/.local/lib/python3.7/site-packages/sqlalchemy/engine/base.py", line 2204, in _handle_dbapi_exception_noconnection
    sqlalchemy_exception, with_traceback=exc_info[2], from_=e
  File "/home/airflow/.local/lib/python3.7/site-packages/sqlalchemy/util/compat.py", line 211, in raise_
    raise exception
  File "/home/airflow/.local/lib/python3.7/site-packages/sqlalchemy/engine/base.py", line 3366, in _wrap_pool_connect
    return fn()
  File "/home/airflow/.local/lib/python3.7/site-packages/sqlalchemy/pool/base.py", line 327, in connect
    return _ConnectionFairy._checkout(self)
  File "/home/airflow/.local/lib/python3.7/site-packages/sqlalchemy/pool/base.py", line 894, in _checkout
    fairy = _ConnectionRecord.checkout(pool)
  File "/home/airflow/.local/lib/python3.7/site-packages/sqlalchemy/pool/base.py", line 493, in checkout
    rec = pool._do_get()
  File "/home/airflow/.local/lib/python3.7/site-packages/sqlalchemy/pool/impl.py", line 256, in _do_get
    return self._create_connection()
  File "/home/airflow/.local/lib/python3.7/site-packages/sqlalchemy/pool/base.py", line 273, in _create_connection
    return _ConnectionRecord(self)
  File "/home/airflow/.local/lib/python3.7/site-packages/sqlalchemy/pool/base.py", line 388, in __init__
    self.__connect()
  File "/home/airflow/.local/lib/python3.7/site-packages/sqlalchemy/pool/base.py", line 691, in __connect
    pool.logger.debug("Error on connect(): %s", e)
  File "/home/airflow/.local/lib/python3.7/site-packages/sqlalchemy/util/langhelpers.py", line 72, in __exit__
    with_traceback=exc_tb,
  File "/home/airflow/.local/lib/python3.7/site-packages/sqlalchemy/util/compat.py", line 211, in raise_
    raise exception
  File "/home/airflow/.local/lib/python3.7/site-packages/sqlalchemy/pool/base.py", line 686, in __connect
    self.dbapi_connection = connection = pool._invoke_creator(self)
  File "/home/airflow/.local/lib/python3.7/site-packages/sqlalchemy/engine/create.py", line 574, in connect
    return dialect.connect(*cargs, **cparams)
  File "/home/airflow/.local/lib/python3.7/site-packages/sqlalchemy/engine/default.py", line 598, in connect
    return self.dbapi.connect(*cargs, **cparams)
  File "/home/airflow/.local/lib/python3.7/site-packages/psycopg2/__init__.py", line 122, in connect
    conn = _connect(dsn, connection_factory=connection_factory, **kwasync)
sqlalchemy.exc.OperationalError: (psycopg2.OperationalError) could not translate host name "postgres" to address: Temporary failure in name resolution

(Background on this error at: https://sqlalche.me/e/14/e3q8)
[2024-10-16T18:11:43.436+0000] {logging_mixin.py:149} INFO - Pushed to XCom: Key: SUI, Value: [[1728259200000, '1.84090000', '2.16800000', '1.83640000', '2.01730000', '191514458.70000000', 1728345599999, '385497166.31088000', 937214, '97872860.70000000', '197125781.07188000', '0'], [1728345600000, '2.01730000', '2.13470000', '1.92950000', '1.98680000', '147218821.70000000', 1728431999999, '297046894.50953000', 714963, '76994797.00000000', '155339375.20641000', '0'], [1728432000000, '1.98690000', '1.99740000', '1.84350000', '1.87550000', '118288209.70000000', 1728518399999, '227579008.21677000', 549488, '59190482.90000000', '113868134.87768000', '0'], [1728518400000, '1.87560000', '1.90490000', '1.74670000', '1.83450000', '109114892.50000000', 1728604799999, '198903082.98708000', 526100, '53858444.50000000', '98220848.23254000', '0'], [1728604800000, '1.83470000', '2.08760000', '1.79000000', '2.05400000', '132738620.20000000', 1728691199999, '260806572.95123000', 642281, '68410657.10000000', '134572128.93377000', '0'], [1728691200000, '2.05400000', '2.28820000', '2.00320000', '2.24150000', '130700373.50000000', 1728777599999, '282217223.15618000', 626545, '70457852.40000000', '152187562.12109000', '0'], [1728777600000, '2.24200000', '2.36800000', '2.12350000', '2.34380000', '115307630.40000000', 1728863999999, '257246254.55338000', 601981, '63935745.30000000', '142780521.81575000', '0']]
[2024-10-16T18:11:43.443+0000] {python.py:183} INFO - Done. Returned value was: None
[2024-10-16T18:11:43.475+0000] {taskinstance.py:1350} INFO - Marking task as SUCCESS. dag_id=api_binance_dag1, task_id=SUI, execution_date=20241014T090000, start_date=20241016T181047, end_date=20241016T181143
[2024-10-16T18:11:43.642+0000] {local_task_job_runner.py:225} INFO - Task exited with return code 0
[2024-10-16T18:11:43.843+0000] {taskinstance.py:2653} INFO - 0 downstream tasks scheduled from follow-on schedule check
